Workbook

Sheet 1. Ficha
A1: FICHA DEL CENTRO DE DISTRIBUCIÓN
B2: Variable | C2: Valor | D2: Importancia
A3: 1 | B3: Nombre / ciudad del CEDI y año de construcción
A4: 2 | B4: Tenencia: propio / arrendado / operado por un operador logístico
A5: 3 | B5: Turnos y días de operación
A6: 4 | B6: Personas: directas / temporales / contratistas
A7: 5 | B7: Área cubierta, número de sectores y altura máxima de almacenamiento | D7: Pérdida máxima probable; sobre 7,6 m cambian los criterios de incendio
A8: 6 | B8: Capacidad portante y planitud del piso (con fecha de medición) | D8: Restringe la carga de montantes y define si el piso admite la altura de elevación
A9: 7 | B9: Posiciones de estiba y % de ocupación promedio y pico | D9: Sobre el 85-90% aparecen bloqueos, almacenamiento improvisado y accidentes
A10: 8 | B10: Unidades o pallets movidos por día y estacionalidad
A11: 9 | B11: Familias de producto y clasificación para incendio (plásticos, aerosoles, litio) | D11: Determina si el sistema de rociadores instalado sigue siendo válido
A12: 10 | B12: ¿Cadena de frío? ¿Mercancías peligrosas? ¿Alto valor? ¿Producto regulado? | D12: Cada una activa riesgos sanitarios, de segregación o de hurto
A13: 11 | B13: Tipo de estantería, altura y ancho de pasillo
A14: 12 | B14: ¿Hay una persona designada como responsable de la seguridad de la estantería? Fecha de la última inspección experta y daños rojo / ámbar
A15: 13 | B15: Equipos: cantidad, tipo, energía y operadores certificados
A16: 14 | B16: Muelles: número, tipo y ¿anclaje del vehículo al muelle (dock lock) o calzos?
A17: 15 | B17: Protección contra incendio: tipo de rociadores, año y última certificación
A18: 16 | B18: Respaldo de energía y última termografía de tableros
A19: 17 | B19: Amenaza sísmica, ¿zona inundable? y ¿la estantería tiene diseño sísmico?
A20: 18 | B20: Valor del inventario pico vs. valor asegurado y recomendaciones abiertas
A21: 19 | B21: Eventos de los últimos 5 años (incendio, colapso, accidente, hurto, inundación)

Sheet 2. Matriz 
A1: ID | B1: Categoría | C1: RIESGO Y QUÉ VERIFICAR | D1: Evidencia o registro que debe existir | E1: P | F1: I | G1: P×I | H1: Nivel | I1: Frecuencia mínima según el nivel (calculada) | J1: Frecuencia técnica que exige la norma | K1: Cumple | L1: Hallazgo y acción requerida | M1: Responsable | N1: Fecha
A2: R-01 | B2: A. Edificio y piso | C2: ESTRUCTURA Y CUBIERTA. Columnas sin impacto ni corrosión y con protectores; canales, bajantes y tragantes limpios antes de lluvias. | D2: Informe estructural firmado y orden de limpieza de cubierta. | E2: 5 | F2: 5 | G2: =IF(OR($E2="",$F2=""),"",$E2*$F2) -> 25 | H2: =IF($G2="","",IF($G2>=20,"Extremo",IF($G2>=12,"Alto",IF($G2>=6,"Medio",IF($G2>=3,"Bajo","Muy bajo"))))) -> Extremo | I2: =IFERROR(VLOOKUP($H2,'4. Escalas'!$A$21:$C$25,3,FALSE),"") -> Diaria o por turno + inspección formal semanal | J2: Visual mensual · evaluación estructural cada 1-3 años y tras sismo · cubierta trimestral (NSR-10 / ASCE 7)
A3: R-02 | B3: A. Edificio y piso | C3: SECTORIZACIÓN CONTRA INCENDIO. Muros cortafuego completos hasta cubierta, sellos en pasos de ductos y cables, puertas cortafuego con cierre libre. | D3: Certificado de sellos y checklist de puertas. | E3: 3 | F3: 5 | G3: =IF(OR($E3="",$F3=""),"",$E3*$F3) -> 15 | H3: =IF($G3="","",IF($G3>=20,"Extremo",IF($G3>=12,"Alto",IF($G3>=6,"Medio",IF($G3>=3,"Bajo","Muy bajo"))))) -> Alto | I3: =IFERROR(VLOOKUP($H3,'4. Escalas'!$A$21:$C$25,3,FALSE),"") -> Semanal + inspección formal mensual | J3: Trimestral (NFPA 80 / NFPA 221)
A4: R-03 | B4: A. Edificio y piso | C4: PISO — CAPACIDAD, PLANITUD Y FISURAS. Capacidad portante vs. carga actual, planitud acorde a la altura de elevación y ausencia de fisuras bajo placas base. | D4: Estudio de piso y mapa de fisuras. | E4: 3 | F4: 5 | G4: =IF(OR($E4="",$F4=""),"",$E4*$F4) -> 15 | H4: =IF($G4="","",IF($G4>=20,"Extremo",IF($G4>=12,"Alto",IF($G4>=6,"Medio",IF($G4>=3,"Bajo","Muy bajo"))))) -> Alto | I4: =IFERROR(VLOOKUP($H4,'4. Escalas'!$A$21:$C$25,3,FALSE),"") -> Semanal + inspección formal mensual | J4: Semestral · perfilometría cada 2-3 años en pasillo estrecho (EN 15620 / TR34 / ACI 302)
A5: R-04 | B5: A. Edificio y piso | C5: PISO — JUNTAS, REJILLAS Y TRANSICIONES. Sellante y bordes de junta sanos, rejillas y tapas a nivel y con clase de carga adecuada. | D5: Mapa de juntas y programa de resellado. | E5: 4 | F5: 3 | G5: =IF(OR($E5="",$F5=""),"",$E5*$F5) -> 12 | H5: =IF($G5="","",IF($G5>=20,"Extremo",IF($G5>=12,"Alto",IF($G5>=6,"Medio",IF($G5>=3,"Bajo","Muy bajo"))))) -> Alto | I5: =IFERROR(VLOOKUP($H5,'4. Escalas'!$A$21:$C$25,3,FALSE),"") -> Semanal + inspección formal mensual | J5: Trimestral · resellado cada 2 a 5 años (ACI 302 / TR34 / EN 124)
A6: R-05 | B6: A. Edificio y piso | C6: PISO — MUELLES, RAMPAS Y ZONAS ESPECIALES. Franja frente a muelles sin hundimientos, rampas con textura y drenaje, contención en zonas de baterías y químicos, y niveles del piso en cámaras de congelación. | D6: Checklist por muelle y registro de niveles. | E6: 4 | F6: 3 | G6: =IF(OR($E6="",$F6=""),"",$E6*$F6) -> 12 | H6: =IF($G6="","",IF($G6>=20,"Extremo",IF($G6>=12,"Alto",IF($G6>=6,"Medio",IF($G6>=3,"Bajo","Muy bajo"))))) -> Alto | I6: =IFERROR(VLOOKUP($H6,'4. Escalas'!$A$21:$C$25,3,FALSE),"") -> Semanal + inspección formal mensual | J6: Trimestral · niveles de cámara de congelación anual (ACI 302 / ANSI B56.1 / NFPA 30 / IIAR)
A7: R-06 | B7: A. Edificio y piso | C7: PISO — DESLIZAMIENTO Y HUMEDAD. Superficie antideslizante en zonas húmedas, atención inmediata de derrames y ausencia de condensación recurrente. | D7: Evaluación de deslizamiento y procedimiento de derrames. | E7: 4 | F7: 3 | G7: =IF(OR($E7="",$F7=""),"",$E7*$F7) -> 12 | H7: =IF($G7="","",IF($G7>=20,"Extremo",IF($G7>=12,"Alto",IF($G7>=6,"Medio",IF($G7>=3,"Bajo","Muy bajo"))))) -> Alto | I7: =IFERROR(VLOOKUP($H7,'4. Escalas'!$A$21:$C$25,3,FALSE),"") -> Semanal + inspección formal mensual | J7: Ronda diaria · evaluación semestral (ANSI A326.3 / DIN 51130 / ASTM F2170)
A8: R-07 | B8: A. Edificio y piso | C8: PISO — SUPERFICIE, DEMARCACIÓN Y REPARACIONES. Sin desprendimiento ni polvo de concreto; demarcación visible de pasillos, senderos y ubicaciones; reparaciones sin desnivel. | D8: Plano de demarcación e historial de reparaciones. | E8: 4 | F8: 3 | G8: =IF(OR($E8="",$F8=""),"",$E8*$F8) -> 12 | H8: =IF($G8="","",IF($G8>=20,"Extremo",IF($G8>=12,"Alto",IF($G8>=6,"Medio",IF($G8>=3,"Bajo","Muy bajo"))))) -> Alto | I8: =IFERROR(VLOOKUP($H8,'4. Escalas'!$A$21:$C$25,3,FALSE),"") -> Semanal + inspección formal mensual | J8: Demarcación mensual (repintado anual) · superficie y reparaciones semestral (ACI 302 / ACI 546)
A9: R-08 | B9: B. Estantería | C9: CAPACIDAD DE CARGA. Placa de carga visible por módulo y peso real del pallet dentro de la capacidad declarada. | D9: Memoria de cálculo del fabricante y muestreo de pesaje. | E9: 1 | F9: 5 | G9: =IF(OR($E9="",$F9=""),"",$E9*$F9) -> 5 | H9: =IF($G9="","",IF($G9>=20,"Extremo",IF($G9>=12,"Alto",IF($G9>=6,"Medio",IF($G9>=3,"Bajo","Muy bajo"))))) -> Bajo | I9: =IFERROR(VLOOKUP($H9,'4. Escalas'!$A$21:$C$25,3,FALSE),"") -> Semestral | J9: Verificación semanal · inspección experta anual (EN 15635 / EN 15512 / RMI MH16.1)
A10: R-09 | B10: B. Estantería | C10: DAÑO POR IMPACTO. Recorrido con clasificación verde / ámbar / rojo; los módulos ROJOS se descargan y bloquean de inmediato. | D10: Formato de inspección con código de módulo y orden de reparación. | E10: 1 | F10: 5 | G10: =IF(OR($E10="",$F10=""),"",$E10*$F10) -> 5 | H10: =IF($G10="","",IF($G10>=20,"Extremo",IF($G10>=12,"Alto",IF($G10>=6,"Medio",IF($G10>=3,"Bajo","Muy bajo"))))) -> Bajo | I10: =IFERROR(VLOOKUP($H10,'4. Escalas'!$A$21:$C$25,3,FALSE),"") -> Semestral | J10: Reporte inmediato de cualquier trabajador · recorrido semanal del responsable de la seguridad de la estantería · experta anual (EN 15635 §9)
A11: R-10 | B11: B. Estantería | C11: ANCLAJES Y CONECTORES. Montantes anclados con el torque especificado, placas base sanas y pasadores de seguridad en todas las vigas. | D11: Protocolo de torque y checklist de pasadores por zona. | E11: 4 | F11: 5 | G11: =IF(OR($E11="",$F11=""),"",$E11*$F11) -> 20 | H11: =IF($G11="","",IF($G11>=20,"Extremo",IF($G11>=12,"Alto",IF($G11>=6,"Medio",IF($G11>=3,"Bajo","Muy bajo"))))) -> Extremo | I11: =IFERROR(VLOOKUP($H11,'4. Escalas'!$A$21:$C$25,3,FALSE),"") -> Diaria o por turno + inspección formal semanal | J11: Pasadores mensual (muestreo) · anclajes y torque anual y tras sismo (EN 15629 / EN 15635)
A12: R-11 | B12: B. Estantería | C12: PROTECCIÓN PERIMETRAL Y ANTIDERRUMBE. Protectores de columna y guardarraíles en esquinas, extremos de pasillo y zonas de tránsito; malla donde la estantería da a zonas de personal. | D12: Plano de protecciones. | E12: 4 | F12: 4 | G12: =IF(OR($E12="",$F12=""),"",$E12*$F12) -> 16 | H12: =IF($G12="","",IF($G12>=20,"Extremo",IF($G12>=12,"Alto",IF($G12>=6,"Medio",IF($G12>=3,"Bajo","Muy bajo"))))) -> Alto | I12: =IFERROR(VLOOKUP($H12,'4. Escalas'!$A$21:$C$25,3,FALSE),"") -> Semanal + inspección formal mensual | J12: Protectores mensual · mallas y barreras trimestral (EN 15635 / EN 15512)
A13: R-12 | B13: B. Estantería | C13: SISTEMAS ESPECIALES: COMPACTO Y ENTREPISO. Guías, rieles y topes de la estantería compacta alineados; entrepiso con placa de carga, barandas, rodapiés y compuerta con enclavamiento. | D13: Memoria del entrepiso y mantenimiento del fabricante. | E13: 3 | F13: 5 | G13: =IF(OR($E13="",$F13=""),"",$E13*$F13) -> 15 | H13: =IF($G13="","",IF($G13>=20,"Extremo",IF($G13>=12,"Alto",IF($G13>=6,"Medio",IF($G13>=3,"Bajo","Muy bajo"))))) -> Alto | I13: =IFERROR(VLOOKUP($H13,'4. Escalas'!$A$21:$C$25,3,FALSE),"") -> Semanal + inspección formal mensual | J13: Compacto visual semanal y especializado semestral · entrepiso trimestral (EN 15635 / Res. 1409 de 2012)
... A63: R-62 | B63: O. Legal y continuidad | C63: LECCIONES APRENDIDAS Y CIERRE DE ACCIONES. Investigación de todos los eventos incluidos los casi-accidentes, causa raíz, cierre y verificación de eficacia. | D63: Matriz de acciones con verificación de eficacia. | E63: 3 | F63: 4 | G63: =IF(OR($E63="",$F63=""),"",$E63*$F63) -> 12 | H63: =IF($G63="","",IF($G63>=20,"Extremo",IF($G63>=12,"Alto",IF($G63>=6,"Medio",IF($G63>=3,"Bajo","Muy bajo"))))) -> Alto | I63: =IFERROR(VLOOKUP($H63,'4. Escalas'!$A$21:$C$25,3,FALSE),"") -> Semanal + inspección formal mensual | J63: Revisión de eventos mensual · análisis de tendencia trimestral (ISO 45001 / ISO 31000)

Sheet 3. Resumen
B1: RESUMEN
B2: Se actualiza solo a partir de la hoja '2. Matriz rápida'.
A4: PERFIL DE RIESGO
B5: Nivel | C5: Cantidad | D5: % | E5: Frecuencia mínima que exige
B6: Extremo | C6: =COUNTIF('2. Matriz '!$H$2:$H$63,"Extremo") -> 7 | D6: =IFERROR(C6/$C$11,0) -> 0.11290323 | E6: Diaria o por turno + inspección formal semanal
B7: Alto | C7: =COUNTIF('2. Matriz '!$H$2:$H$63,"Alto") -> 44 | D7: =IFERROR(C7/$C$11,0) -> 0.70967742 | E7: Semanal + inspección formal mensual
B8: Medio | C8: =COUNTIF('2. Matriz '!$H$2:$H$63,"Medio") -> 9 | D8: =IFERROR(C8/$C$11,0) -> 0.14516129 | E8: Mensual (operativo) o trimestral (estructural)
B9: Bajo | C9: =COUNTIF('2. Matriz '!$H$2:$H$63,"Bajo") -> 2 | D9: =IFERROR(C9/$C$11,0) -> 0.032258065 | E9: Semestral
B10: Muy bajo | C10: =COUNTIF('2. Matriz '!$H$2:$H$63,"Muy bajo") -> 0 | D10: =IFERROR(C10/$C$11,0) -> 0 | E10: Anual
B11: Total de riesgos | C11: =SUM(C6:C10) -> 62
A13: CUMPLIMIENTO DE LA VERIFICACIÓN
B14: Resultado | C14: Cantidad | D14: % | E14: Qué hacer
B15: Sí | C15: =COUNTIF('2. Matriz '!$K$2:$K$63,"Sí") -> 0 | D15: =IFERROR(C15/62,0) -> 0 | E15: Mantener el control y conservar su evidencia
B16: Parcial | C16: =COUNTIF('2. Matriz '!$K$2:$K$63,"Parcial") -> 0 | D16: =IFERROR(C16/62,0) -> 0 | E16: Cerrar la brecha dentro del plazo del nivel de riesgo
B17: No | C17: =COUNTIF('2. Matriz '!$K$2:$K$63,"No") -> 0 | D17: =IFERROR(C17/62,0) -> 0 | E17: Pasa al plan de acción con responsable y fecha
B18: N.A. | C18: =COUNTIF('2. Matriz '!$K$2:$K$63,"N.A.") -> 0 | D18: =IFERROR(C18/62,0) -> 0 | E18: Dejar registrado por qué no aplica
B19: Sin marcar | C19: =62-COUNTA('2. Matriz '!$K$2:$K$63) -> 62 | D19: =IFERROR(C19/62,0) -> 1 | E19: Pendiente de verificar en campo
B20: Índice de cumplimiento | C20: =IFERROR(C15/(C15+C16+C17),0) -> 0 | E20: Sí ÷ (Sí + Parcial + No)
B21: Incumplimientos en riesgo Extremo o Alto | C21: =COUNTIFS('2. Matriz '!$H$2:$H$63,"Extremo",'2. Matriz '!$K$2:$K$63,"No")+COUNTIFS('2. Matriz '!$H$2:$H$63,"Alto",'2. Matriz '!$K$2:$K$63,"No") -> 0 | E21: Se atienden primero: ≤ 15 días (Extremo) y ≤ 30 días (Alto)
A23: POR CATEGORÍA
B24: Categoría | C24: Extremo | D24: Alto | E24: Medio | F24: Bajo | G24: Muy bajo | H24: Total
B25: A. Edificio y piso | C25: =COUNTIFS('2. Matriz '!$B$2:$B$63,$B25,'2. Matriz '!$H$2:$H$63,"Extremo") -> 1 | D25: =COUNTIFS('2. Matriz '!$B$2:$B$63,$B25,'2. Matriz '!$H$2:$H$63,"Alto") -> 6 | E25: =COUNTIFS('2. Matriz '!$B$2:$B$63,$B25,'2. Matriz '!$H$2:$H$63,"Medio") -> 0 | F25: =COUNTIFS('2. Matriz '!$B$2:$B$63,$B25,'2. Matriz '!$H$2:$H$63,"Bajo") -> 0 | G25: =COUNTIFS('2. Matriz '!$B$2:$B$63,$B25,'2. Matriz '!$H$2:$H$63,"Muy bajo") -> 0 | H25: =COUNTIF('2. Matriz '!$B$2:$B$63,$B25) -> 7
B26: B. Estantería | C26: =COUNTIFS('2. Matriz '!$B$2:$B$63,$B26,'2. Matriz '!$H$2:$H$63,"Extremo") -> 1 | D26: =COUNTIFS('2. Matriz '!$B$2:$B$63,$B26,'2. Matriz '!$H$2:$H$63,"Alto") -> 4 | E26: =COUNTIFS('2. Matriz '!$B$2:$B$63,$B26,'2. Matriz '!$H$2:$H$63,"Medio") -> 0 | F26: =COUNTIFS('2. Matriz '!$B$2:$B$63,$B26,'2. Matriz '!$H$2:$H$63,"Bajo") -> 2 | G26: =COUNTIFS('2. Matriz '!$B$2:$B$63,$B26,'2. Matriz '!$H$2:$H$63,"Muy bajo") -> 0 | H26: =COUNTIF('2. Matriz '!$B$2:$B$63,$B26) -> 7
B27: C. Volumen y ocupación | C27: =COUNTIFS('2. Matriz '!$B$2:$B$63,$B27,'2. Matriz '!$H$2:$H$63,"Extremo") -> 2 | D27: =COUNTIFS('2. Matriz '!$B$2:$B$63,$B27,'2. Matriz '!$H$2:$H$63,"Alto") -> 1 | E27: =COUNTIFS('2. Matriz '!$B$2:$B$63,$B27,'2. Matriz '!$H$2:$H$63,"Medio") -> 0 | F27: =COUNTIFS('2. Matriz '!$B$2:$B$63,$B27,'2. Matriz '!$H$2:$H$63,"Bajo") -> 0 | G27: =COUNTIFS('2. Matriz '!$B$2:$B$63,$B27,'2. Matriz '!$H$2:$H$63,"Muy bajo") -> 0 | H27: =COUNTIF('2. Matriz '!$B$2:$B$63,$B27) -> 3
B28: D. Muelles y patio | C28: =COUNTIFS('2. Matriz '!$B$2:$B$63,$B28,'2. Matriz '!$H$2:$H$63,"Extremo") -> 0 | D28: =COUNTIFS('2. Matriz '!$B$2:$B$63,$B28,'2. Matriz '!$H$2:$H$63,"Alto") -> 4 | E28: =COUNTIFS('2. Matriz '!$B$2:$B$63,$B28,'2. Matriz '!$H$2:$H$63,"Medio") -> 0 | F28: =COUNTIFS('2. Matriz '!$B$2:$B$63,$B28,'2. Matriz '!$H$2:$H$63,"Bajo") -> 0 | G28: =COUNTIFS('2. Matriz '!$B$2:$B$63,$B28,'2. Matriz '!$H$2:$H$63,"Muy bajo") -> 0 | H28: =COUNTIF('2. Matriz '!$B$2:$B$63,$B28) -> 4
B29: E. Equipos (manipulación de materiales) | C29: =COUNTIFS('2. Matriz '!$B$2:$B$63,$B29,'2. Matriz '!$H$2:$H$63,"Extremo") -> 1 | D29: =COUNTIFS('2. Matriz '!$B$2:$B$63,$B29,'2. Matriz '!$H$2:$H$63,"Alto") -> 4 | E29: =COUNTIFS('2. Matriz '!$B$2:$B$63,$B29,'2. Matriz '!$H$2:$H$63,"Medio") -> 0 | F29: =COUNTIFS('2. Matriz '!$B$2:$B$63,$B29,'2. Matriz '!$H$2:$H$63,"Bajo") -> 0 | G29: =COUNTIFS('2. Matriz '!$B$2:$B$63,$B29,'2. Matriz '!$H$2:$H$63,"Muy bajo") -> 0 | H29: =COUNTIF('2. Matriz '!$B$2:$B$63,$B29) -> 5
B30: F. Incendio | C30: =COUNTIFS('2. Matriz '!$B$2:$B$63,$B30,'2. Matriz '!$H$2:$H$63,"Extremo") -> 2 | D30: =COUNTIFS('2. Matriz '!$B$2:$B$63,$B30,'2. Matriz '!$H$2:$H$63,"Alto") -> 4 | E30: =COUNTIFS('2. Matriz '!$B$2:$B$63,$B30,'2. Matriz '!$H$2:$H$63,"Medio") -> 1 | F30: =COUNTIFS('2. Matriz '!$B$2:$B$63,$B30,'2. Matriz '!$H$2:$H$63,"Bajo") -> 0 | G30: =COUNTIFS('2. Matriz '!$B$2:$B$63,$B30,'2. Matriz '!$H$2:$H$63,"Muy bajo") -> 0 | H30: =COUNTIF('2. Matriz '!$B$2:$B$63,$B30) -> 7
B31: G. Riesgos naturales | C31: =COUNTIFS('2. Matriz '!$B$2:$B$63,$B31,'2. Matriz '!$H$2:$H$63,"Extremo") -> 0 | D31: =COUNTIFS('2. Matriz '!$B$2:$B$63,$B31,'2. Matriz '!$H$2:$H$63,"Alto") -> 1 | E31: =COUNTIFS('2. Matriz '!$B$2:$B$63,$B31,'2. Matriz '!$H$2:$H$63,"Medio") -> 2 | F31: =COUNTIFS('2. Matriz '!$B$2:$B$63,$B31,'2. Matriz '!$H$2:$H$63,"Bajo") -> 0 | G31: =COUNTIFS('2. Matriz '!$B$2:$B$63,$B31,'2. Matriz '!$H$2:$H$63,"Muy bajo") -> 0 | H31: =COUNTIF('2. Matriz '!$B$2:$B$63,$B31) -> 3
B32: H. Eléctrico y servicios | C32: =COUNTIFS('2. Matriz '!$B$2:$B$63,$B32,'2. Matriz '!$H$2:$H$63,"Extremo") -> 0 | D32: =COUNTIFS('2. Matriz '!$B$2:$B$63,$B32,'2. Matriz '!$H$2:$H$63,"Alto") -> 2 | E32: =COUNTIFS('2. Matriz '!$B$2:$B$63,$B32,'2. Matriz '!$H$2:$H$63,"Medio") -> 0 | F32: =COUNTIFS('2. Matriz '!$B$2:$B$63,$B32,'2. Matriz '!$H$2:$H$63,"Bajo") -> 0 | G32: =COUNTIFS('2. Matriz '!$B$2:$B$63,$B32,'2. Matriz '!$H$2:$H$63,"Muy bajo") -> 0 | H32: =COUNTIF('2. Matriz '!$B$2:$B$63,$B32) -> 2
B33: I. Seguridad física | C33: =COUNTIFS('2. Matriz '!$B$2:$B$63,$B33,'2. Matriz '!$H$2:$H$63,"Extremo") -> 0 | D33: =COUNTIFS('2. Matriz '!$B$2:$B$63,$B33,'2. Matriz '!$H$2:$H$63,"Alto") -> 2 | E33: =COUNTIFS('2. Matriz '!$B$2:$B$63,$B33,'2. Matriz '!$H$2:$H$63,"Medio") -> 2 | F33: =COUNTIFS('2. Matriz '!$B$2:$B$63,$B33,'2. Matriz '!$H$2:$H$63,"Bajo") -> 0 | G33: =COUNTIFS('2. Matriz '!$B$2:$B$63,$B33,'2. Matriz '!$H$2:$H$63,"Muy bajo") -> 0 | H33: =COUNTIF('2. Matriz '!$B$2:$B$63,$B33) -> 4
B34: J. Tecnología | C34: =COUNTIFS('2. Matriz '!$B$2:$B$63,$B34,'2. Matriz '!$H$2:$H$63,"Extremo") -> 0 | D34: =COUNTIFS('2. Matriz '!$B$2:$B$63,$B34,'2. Matriz '!$H$2:$H$63,"Alto") -> 2 | E34: =COUNTIFS('2. Matriz '!$B$2:$B$63,$B34,'2. Matriz '!$H$2:$H$63,"Medio") -> 0 | F34: =COUNTIFS('2. Matriz '!$B$2:$B$63,$B34,'2. Matriz '!$H$2:$H$63,"Bajo") -> 0 | G34: =COUNTIFS('2. Matriz '!$B$2:$B$63,$B34,'2. Matriz '!$H$2:$H$63,"Muy bajo") -> 0 | H34: =COUNTIF('2. Matriz '!$B$2:$B$63,$B34) -> 2
B35: K. Personas (SST) | C35: =COUNTIFS('2. Matriz '!$B$2:$B$63,$B35,'2. Matriz '!$H$2:$H$63,"Extremo") -> 0 | D35: =COUNTIFS('2. Matriz '!$B$2:$B$63,$B35,'2. Matriz '!$H$2:$H$63,"Alto") -> 4 | E35: =COUNTIFS('2. Matriz '!$B$2:$B$63,$B35,'2. Matriz '!$H$2:$H$63,"Medio") -> 1 | F35: =COUNTIFS('2. Matriz '!$B$2:$B$63,$B35,'2. Matriz '!$H$2:$H$63,"Bajo") -> 0 | G35: =COUNTIFS('2. Matriz '!$B$2:$B$63,$B35,'2. Matriz '!$H$2:$H$63,"Muy bajo") -> 0 | H35: =COUNTIF('2. Matriz '!$B$2:$B$63,$B35) -> 5
B36: L. Producto y calidad | C36: =COUNTIFS('2. Matriz '!$B$2:$B$63,$B36,'2. Matriz '!$H$2:$H$63,"Extremo") -> 0 | D36: =COUNTIFS('2. Matriz '!$B$2:$B$63,$B36,'2. Matriz '!$H$2:$H$63,"Alto") -> 5 | E36: =COUNTIFS('2. Matriz '!$B$2:$B$63,$B36,'2. Matriz '!$H$2:$H$63,"Medio") -> 0 | F36: =COUNTIFS('2. Matriz '!$B$2:$B$63,$B36,'2. Matriz '!$H$2:$H$63,"Bajo") -> 0 | G36: =COUNTIFS('2. Matriz '!$B$2:$B$63,$B36,'2. Matriz '!$H$2:$H$63,"Muy bajo") -> 0 | H36: =COUNTIF('2. Matriz '!$B$2:$B$63,$B36) -> 5
... B39: O. Legal y continuidad | C39: =COUNTIFS('2. Matriz '!$B$2:$B$63,$B39,'2. Matriz '!$H$2:$H$63,"Extremo") -> 0 | D39: =COUNTIFS('2. Matriz '!$B$2:$B$63,$B39,'2. Matriz '!$H$2:$H$63,"Alto") -> 2 | E39: =COUNTIFS('2. Matriz '!$B$2:$B$63,$B39,'2. Matriz '!$H$2:$H$63,"Medio") -> 2 | F39: =COUNTIFS('2. Matriz '!$B$2:$B$63,$B39,'2. Matriz '!$H$2:$H$63,"Bajo") -> 0 | G39: =COUNTIFS('2. Matriz '!$B$2:$B$63,$B39,'2. Matriz '!$H$2:$H$63,"Muy bajo") -> 0 | H39: =COUNTIF('2. Matriz '!$B$2:$B$63,$B39) -> 4

Sheet 4. Escalas
A1: ESCALAS, MATRIZ Y CRITERIOS DE FRECUENCIA
A3: PROBABILIDAD — ¿qué tan factible es que ocurra?
A4: Valor | B4: Descriptor | C4: Criterio de frecuencia | D4: Histórico en la instalación | E4: Estado del control
A5: 1 | B5: Raro | C5: Menos de 1 vez cada 10 años | D5: Nunca ha ocurrido aquí ni en el sector | E5: Control robusto y verificado
A6: 2 | B6: Improbable | C6: 1 vez cada 5 a 10 años | D6: Ha ocurrido en el sector, no aquí | E6: Control funciona, desviaciones menores
A7: 3 | B7: Posible | C7: 1 vez cada 1 a 5 años | D7: Ya ocurrió al menos una vez aquí | E7: Control existe, cumplimiento irregular
A8: 4 | B8: Probable | C8: Varias veces al año | D8: Recurrente; hay casi-accidentes | E8: Control débil o informal
A9: 5 | B9: Casi seguro | C9: Mensual o más frecuente | D9: Es parte del día a día | E9: No hay control o está fuera de servicio
A11: IMPACTO — se toma el PEOR de los criterios
A12: Valor | B12: Descriptor | C12: Personas | D12: Operación y continuidad | E12: Económico | F12: Legal y reputacional
A13: 1 | B13: Insignificante | C13: Sin lesión | D13: Sin afectación del servicio | E13: Pérdida marginal | F13: Sin consecuencia externa
A14: 2 | B14: Menor | C14: Lesión leve sin incapacidad | D14: Retraso de horas | E14: Cubierta por el presupuesto | F14: Observación de auditoría
A15: 3 | B15: Moderado | C15: Incapacidad temporal | D15: Paro de un turno o proceso | E15: Afecta el resultado del mes | F15: Requerimiento de autoridad o reclamo
A16: 4 | B16: Mayor | C16: Lesión grave o varios lesionados | D16: Paro de varios días | E16: Supera el deducible; afecta el año | F16: Sanción y daño reputacional
A17: 5 | B17: Catastrófico | C17: Una o varias fatalidades | D17: Pérdida del CEDI | E17: Pérdida total o no asegurada | F17: Cierre, responsabilidad penal, retiro masivo de producto
A19: NIVEL DE RIESGO → CADA CUÁNTO REVISAR, EN CUÁNTO ACTUAR Y QUIÉN LO ACEPTA
A20: Nivel | B20: Rango (P × I) | C20: Frecuencia mínima de verificación | D20: Reevaluar el riesgo | E20: Plazo del plan de acción | F20: Quién acepta el riesgo
A21: Extremo | B21: 20 - 25 | C21: Diaria o por turno + inspección formal semanal | D21: Mensual | E21: ≤ 15 días · se interviene o se suspende la actividad | F21: Gerencia / Dirección
A22: Alto | B22: 12 - 16 | C22: Semanal + inspección formal mensual | D22: Trimestral | E22: ≤ 30 días | F22: Jefe de CEDI con visto bueno de Seguridad y Salud en el Trabajo
A23: Medio | B23: 6 - 10 | C23: Mensual (operativo) o trimestral (estructural) | D23: Semestral | E23: ≤ 90 días | F23: Jefe de CEDI
A24: Bajo | B24: 3 - 5 | C24: Semestral | D24: Anual | E24: Siguiente ciclo presupuestal | F24: Coordinador del proceso
A25: Muy bajo | B25: 1 - 2 | C25: Anual | D25: Anual | E25: Solo monitoreo | F25: Coordinador del proceso
A27: MATRIZ 5 × 5 (filas = Probabilidad · columnas = Impacto)
A28: P \ I | B28: 1 | C28: 2 | D28: 3 | E28: 4 | F28: 5
A29: 5 | B29: 5 | C29: 10 | D29: 15 | E29: 20 | F29: 25
A30: 4 | B30: 4 | C30: 8 | D30: 12 | E30: 16 | F30: 20
A31: 3 | B31: 3 | C31: 6 | D31: 9 | E31: 12 | F31: 15
A32: 2 | B32: 2 | C32: 4 | D32: 6 | E32: 8 | F32: 10
A33: 1 | B33: 1 | C33: 2 | D33: 3 | E33: 4 | F33: 5
A34: Si el escenario puede causar una fatalidad, califique el impacto en 5 aunque la probabilidad sea baja: ese riesgo se gestiona por severidad, no por frecuencia.
A36: DISPARADORES DE REVISIÓN EXTRAORDINARIA — obligan a revisar de inmediato, sin esperar la frecuencia
A37: Disparador | B37: Acción inmediata exigida
A38: Sismo sentido | B38: Inspección estructural y de estantería antes de reanudar; no se reingresa personal sin concepto técnico.
A39: Incendio o conato | B39: Investigación de causa, revisión de la carga de fuego y verificación integral del sistema de protección.
A40: Impacto contra estantería | B40: Descarga inmediata del módulo, evaluación verde / ámbar / rojo y reparación con repuesto original.
A41: Accidente grave o casi-accidente de alto potencial | B41: Causa raíz y recalificación de todos los riesgos de la misma familia.
A42: Inundación o vendaval | B42: Revisión de cubierta, drenajes, instalación eléctrica y producto almacenado en piso.
A43: Cambio de la distribución en planta, de altura o de sistema de almacenamiento | B43: Recálculo estructural, revisión del diseño contra incendio y actualización de planos y placas.
A44: Cambio de portafolio (plásticos, aerosoles, litio, químicos) | B44: Reclasificación de la mercancía y validación de rociadores y segregación.
A45: Nuevo tipo de equipo de manipulación | B45: Revisión de flujos, ancho de pasillo, planitud del piso y certificación de operadores.
...

Sheet 5. Plan de acción
A1: N° | B1: ID riesgo | C1: Hallazgo detectado | D1: Nivel | E1: Acción correctiva o preventiva | F1: Tipo de acción | G1: Responsable | H1: Fecha compromiso | I1: Fecha de cierre | J1: % avance | K1: Verificación de eficacia (cómo se comprueba) | L1: Estado
A2: 1
A3: 2
A4: 3
A5: 4
A6: 5
A7: 6
A8: 7
A9: 8
A10: 9
A11: 10
A12: 11
A13: 12
... A36: 35

Sheet 6. Referencias
B1: MARCO NORMATIVO DE REFERENCIA
A2: GESTIÓN DEL RIESGO
A3: # | B3: Norma o estándar | C3: Qué aporta al checklist | D3: Dónde se aplica
A4: 1 | B4: ISO 31000 | C4: Gestión del riesgo: identificar, analizar, evaluar, tratar y monitorear. Es la base metodológica de la matriz y de la escala P × I. | D4: Toda la matriz
A5: 2 | B5: ISO 45001 / Decreto 1072 de 2015 | C5: Sistema de gestión de seguridad y salud en el trabajo. | D5: Bloque K y contratistas
A6: 3 | B6: Resolución 0312 de 2019 (Colombia) | C6: Estándares mínimos del Sistema de Gestión de Seguridad y Salud en el Trabajo (SG-SST) y autoevaluación anual obligatoria. | D6: R-59
A7: 4 | B7: ISO 22301 | C7: Continuidad del negocio: análisis de impacto al negocio, tiempo máximo de recuperación, pérdida máxima de información y prueba del plan. | D7: R-61
A8: 5 | B8: ISO 28000 / BASC / OEA / C-TPAT | C8: Seguridad de la cadena de suministro y protección de la carga. | D8: Bloque I
A9: 6 | B9: ISO 27001 / NIST CSF | C9: Seguridad de la información y ciberseguridad. | D9: R-44
A11: ESTANTERÍA Y PISO
A12: # | B12: Norma o estándar | C12: Qué aporta al checklist | D12: Dónde se aplica
A13: 1 | B13: EN 15635 | C13: Uso y mantenimiento del equipo de almacenamiento: define quién es el responsable de la seguridad de la estantería, la inspección visual periódica, la experta anual y la clasificación de daños verde / ámbar / rojo. | D13: Todo el bloque B
A14: 2 | B14: EN 15512 / RMI ANSI MH16.1 | C14: Diseño estructural de estanterías, incluido el diseño sísmico. | D14: R-08, R-34
A15: 3 | B15: EN 15629 | C15: Especificación e instalación del equipo de almacenamiento. | D15: R-14, R-57
A16: 4 | B16: EN 15620 / TR34 / ACI 302 | C16: Tolerancias del piso, planitud, juntas y acabado de la losa. | D16: R-03, R-04, R-07
A17: 5 | B17: FEM 10.2.08 | C17: Diseño sísmico de sistemas de almacenamiento en estanterías. | D17: R-34
A18: 6 | B18: ANSI A326.3 / DIN 51130 | C18: Resistencia al deslizamiento de superficies. | D18: R-06
A20: PROTECCIÓN CONTRA INCENDIO
A21: # | B21: Norma o estándar | C21: Qué aporta al checklist | D21: Dónde se aplica
A22: 1 | B22: NFPA 13 | C22: Diseño de rociadores: clasificación de mercancía, altura de almacenamiento y 45 cm libres bajo el deflector. | D22: R-16
A23: 2 | B23: NFPA 25 | C23: Inspección, prueba y mantenimiento de sistemas a base de agua. Es la fuente de las frecuencias semanal, mensual, trimestral, anual y quinquenal. | D23: R-27, R-29
A24: 3 | B24: NFPA 10 / NTC 2885 | C24: Extintores portátiles: inspección mensual, mantenimiento anual y prueba hidrostática. | D24: R-29
A25: 4 | B25: NFPA 72 / NFPA 101 / NTC 1700 | C25: Detección y alarma; seguridad humana, salidas, señalización e iluminación de emergencia. | D25: R-28, R-32
A26: 5 | B26: NFPA 30 / 30B / 230 | C26: Líquidos inflamables, aerosoles y protección en almacenamiento (incluye estibas). | D26: R-30
A27: 6 | B27: NFPA 51B / NFPA 80 / NFPA 221 | C27: Trabajos en caliente; puertas y muros cortafuego. | D27: R-02, R-31
A28: 7 | B28: NFPA 855 / NFPA 58 / NFPA 110 | C28: Baterías de litio, gas propano (GLP) y sistemas de energía de emergencia. | D28: R-26, R-38
A29: 8 | B29: FM Global Data Sheets | C29: Guías de aseguradoras: drenaje de cubierta (1-54) y almacenamiento de estibas (8-24). | D29: R-01, R-30
A31: EQUIPOS, INSTALACIONES Y PRODUCTO
A32: # | B32: Norma o estándar | C32: Qué aporta al checklist | D32: Dónde se aplica
A33: 1 | B33: OSHA 1910.178 / ANSI B56.1 | C33: Montacargas: preoperacional por turno, certificación del operador y recertificación cada 3 años, aseguramiento del camión en muelle. | D33: Bloque E, R-18
A34: 2 | B34: ISO 5057 | C34: Inspección de horquillas en servicio (desgaste máximo del 10%). | D34: R-23
A35: 3 | B35: Resolución 1409 de 2012 (Colombia) | C35: Trabajo en alturas: permisos, certificación, anclajes y elementos de protección personal. | D35: R-25, R-47
A36: 4 | B36: ISO 11228 / NIOSH / REBA | C36: Manipulación manual de cargas y evaluación ergonómica. | D36: R-45
A37: 5 | B37: RETIE / RETILAP / NTC 4552 / NFPA 70B | C37: Instalaciones eléctricas, iluminación, protección contra rayos y mantenimiento eléctrico con termografía. | D37: R-31, R-36, R-37
A38: 6 | B38: NSR-10 / ASCE 7 | C38: Norma de construcción sismo resistente: diseño estructural, cargas de cubierta y amenaza sísmica. | D38: R-01, R-34
A39: 7 | B39: Resolución 2674 de 2013 / BPM / HACCP / GDP | C39: Condiciones sanitarias de almacenamiento, cadena de frío y control de plagas. | D39: R-50, R-51
A40: 8 | B40: Decreto 1609 de 2002 / NTC 1692 / SGA-GHS / NFPA 400 | C40: Mercancías peligrosas: clasificación, rotulado y segregación. | D40: R-52
A41: 9 | B41: Decreto 4741 de 2005 / ISO 14001 | C41: Residuos peligrosos y gestión ambiental. | D41: R-05, R-52
A42: 10 | B42: ISO 17712 / IIAR / ASHRAE 15 | C42: Sellos de alta seguridad; seguridad en refrigeración por amoníaco. | D42: R-42, R-38
