Workbook

Sheet Portada
B2: EVALUACIÓN OPERATIVA — CEDI MADRID
B3: Formato de captura en piso · Visita día 1
B5: Hoy no se diagnostica: se captura evidencia propia que después nadie pueda discutir. Cada hoja trae el procedimiento paso a paso, las reglas para no dudar al llenarla y las preguntas que debes hacer según el resultado que te dé. Diligencia solo las celdas amarillas: las grises se calculan solas y alimentan la hoja Resumen.
B8: DATOS DE LA VISITA
B9: Centro de distribución | C9: CEDI Madrid
B10: Fecha de la visita
B11: Día de la semana
B12: Responsable de la evaluación
B13: Jefe del CEDI
B14: Turno observado
B15: Hora de corte de pedidos
B16: Hora de salida del último camión
B18: RUTA DEL DÍA — QUÉ HACES Y DÓNDE LO REGISTRAS
B19: Momento | C19: Qué haces | D19: Dónde lo registras
B20: Al llegar | C20: Apertura de 10 minutos, de pie. Nada de sala de juntas. | D20: 1 Checklist
B21: Primeros 30 min | C21: Etiquetar pallets en piso · abrir planilla en portería · encargar el conteo ciego. | D21: 7 · 6 · 4
B22: Mañana | C22: Recorrido a contracorriente y conteo de ocupación en 5 pasillos. | D22: 2 Ocupación
B23: Mañana | C23: Cronometrar el ciclo completo de 4 operarios. | D23: 3 Ciclo picking
B24: Todo el día | C24: Una ronda de muestreo cada 20 minutos. | D24: 5 Muestreo
B25: Todo el turno | C25: Planilla de agotados en manos de un supervisor de picking. | D25: 8 Agotados
B26: 3 h antes del corte | C26: Segundo recorrido en el pico. Observar chequeo y despacho. | D26: 11 Hallazgos
B27: Al cierre | C27: Cruzar el conteo ciego contra la cantidad del sistema. | D27: 4 Conteo ciego
B28: Últimos 20 min | C28: Devolver tres hechos con número y entregar la solicitud de datos. | D28: 11 · 10
B30: CÓMO SE LEE ESTE ARCHIVO
B31: Celda amarilla | C31: La llenas tú en piso. Al hacer clic aparece una ayuda con qué escribir.
B32: Celda gris | C32: Se calcula sola. No la escribas.
B33: Fila EJEMPLO | C33: Muestra el formato esperado. No entra en los totales. Puedes dejarla.
B34: Bloque verde | C34: Las preguntas que debes hacer si ese indicador sale mal.
B36: Valores de referencia: los cortes usados en este archivo (85–90% de ocupación, 50% de desplazamiento en el ciclo, 95% de ERI, 90 minutos de permanencia en muelle) son referencias de industria para CEDI de consumo masivo con WMS y radiofrecuencia. Sirven para leer lo que midas hoy; conviértelos en meta solo después de calibrarlos contra el histórico propio de Madrid.

Sheet Resumen
A1: RESUMEN DEL DÍA
A2: Se llena solo desde las hojas de captura. Es lo que devuelves en la reunión de cierre: hechos con número, no opiniones.
A4: Indicador | B4: Resultado | C4: Referencia | D4: Estado | E4: Qué significa | F4: Primera acción si está en rojo
A5: Ocupación de posiciones | B5: =IF('2 Ocupación'!$F$38="","",'2 Ocupación'!$F$38) | C5: 80% – 85% | D5: =IF($B5="","—",IF($B5>0.9,"CRÍTICO",IF($B5>0.85,"ATENCIÓN","OK"))) -> — | E5: =IF($B5="","Pendiente de medir",IF($B5>0.9,"Zona de congestión: la productividad que midas hoy está contaminada.",IF($B5>0.85,"En el límite. Cada punto adicional de ocupación ya cuesta caro.","Ocupación sana. Si igual se siente lleno, el problema es de flujo, no de espacio."))) -> Pendiente de medir | F5: Purgar inventario sin movimiento mayor a 180 días antes de cualquier otra iniciativa. El espacio que falta casi siempre ya está adentro.
A6: Capacidad fantasma (posiciones parciales) | B6: =IF('2 Ocupación'!$G$38="","",'2 Ocupación'!$G$38) | C6: menos de 10% | D6: =IF($B6="","—",IF($B6>0.15,"CRÍTICO",IF($B6>0.1,"ATENCIÓN","OK"))) -> — | E6: =IF($B6="","Pendiente de medir",IF($B6>0.15,"Posiciones que el sistema ve ocupadas y no almacenan nada.",IF($B6>0.1,"Hay espacio recuperable sin comprar un metro más.","Sin efecto panal relevante."))) -> Pendiente de medir | F6: Programar consolidación de posiciones parciales el próximo fin de semana. No requiere inversión.
A7: Desplazamiento sobre el ciclo de alistamiento | B7: =IF('3 Ciclo picking'!$F$38="","",'3 Ciclo picking'!$F$38) | C7: menos de 40% | D7: =IF($B7="","—",IF($B7>0.5,"CRÍTICO",IF($B7>0.4,"ATENCIÓN","OK"))) -> — | E7: =IF($B7="","Pendiente de medir",IF($B7>0.5,"El problema es el slotting, no la gente. Correr más rápido no arregla una ruta mal diseñada.",IF($B7>0.4,"Alto pero manejable. Vale un re-slotting de los SKU de mayor rotación.","Desplazamiento razonable. La pérdida está en búsqueda, espera o reproceso."))) -> Pendiente de medir | F7: Re-slotting de los 200 SKU de mayor rotación a la zona dorada. Se hace en un fin de semana.
A8: ERI por ubicación (conteo ciego) | B8: =IF('4 Conteo ciego'!$F$27="","",'4 Conteo ciego'!$F$27) | C8: más de 97% | D8: =IF($B8="","—",IF($B8<0.95,"CRÍTICO",IF($B8<0.97,"ATENCIÓN","OK"))) -> — | E8: =IF($B8="","Pendiente de medir",IF($B8<0.95,"El operario trabaja con información falsa. Es la causa raíz de casi todo lo demás.",IF($B8<0.97,"Aceptable pero no confiable.","Buen ERI. Los errores de despacho tienen otra causa."))) -> Pendiente de medir | F8: Conteo cíclico diario en zona A y restringir quién puede ajustar inventario. Va antes que slotting y que chequeo.
A9: Tiempo que no agrega valor (muestreo) | B9: =IF('5 Muestreo'!$H$39="","",'5 Muestreo'!$H$39) | C9: menos de 35% | D9: =IF($B9="","—",IF($B9>0.5,"CRÍTICO",IF($B9>0.35,"ATENCIÓN","OK"))) -> — | E9: =IF($B9="","Pendiente de medir",IF($B9>0.5,"Más de la mitad del día no agrega valor. Es diseño de la operación, no esfuerzo de la gente.",IF($B9>0.35,"Rango habitual en CEDI sin estándares de trabajo.","Operación con poco desperdicio visible."))) -> Pendiente de medir | F9: Estándar de líneas por hora con tablero visual en piso, y reabastecimiento en ola antes del turno.
A10: Permanencia promedio en muelle (min) | B10: =IF('6 Vehículos'!$H$49="","",'6 Vehículos'!$H$49) | C10: menos de 90 min | D10: =IF($B10="","—",IF($B10>180,"CRÍTICO",IF($B10>90,"ATENCIÓN","OK"))) -> — | E10: =IF($B10="","Pendiente de medir",IF($B10>180,"El cuello de botella está en muelle o en staging, no en alistamiento.",IF($B10>90,"Revisar programación de citas y secuencia de cargue.","Muelle fluido."))) -> Pendiente de medir | F10: Sistema de citas y alistar contra la hora de cita, no contra el corte. Empezar por las rutas de mayor volumen.
A11: Pallets en piso etiquetados hoy | B11: =IF('7 Pallets en piso'!$B$38="","",'7 Pallets en piso'!$B$38) | C11: 0 | D11: =IF($B11="","—",IF($B11>30,"CRÍTICO",IF($B11>0,"ATENCIÓN","OK"))) -> — | E11: =IF($B11="","Pendiente de medir",IF($B11>30,"Backlog físico grande. Verificar a las 48 h cuántos siguen con la etiqueta original.",IF($B11>0,"Verificar a las 48 h cuáles no se movieron.","Sin producto fuera de posición."))) -> Pendiente de medir | F11: Fijar meta de dock-to-stock menor a 4 horas y regla de piso libre al cierre de cada turno, con verificación diaria.
A12: Agotados internos de picking en el turno | B12: =IF('8 Agotados'!$B$68="","",'8 Agotados'!$B$68) | C12: 0 | D12: =IF($B12="","—",IF($B12>10,"CRÍTICO",IF($B12>0,"ATENCIÓN","OK"))) -> — | E12: =IF($B12="","Pendiente de medir",IF($B12>10,"El reabastecimiento va detrás del picking y detiene al operario varias veces al día.",IF($B12>0,"Cuantificar los minutos perdidos por evento.","El reabastecimiento va adelante del picking."))) -> Pendiente de medir | F12: Pasar el reabastecimiento a ola antes del turno y revisar el punto de reorden de los SKU que se repiten.
A13: Avance del checklist del día | B13: =IF('1 Checklist'!$D$3="","",'1 Checklist'!$D$3) -> 0 | C13: 100% | D13: =IF($B13="","—",IF($B13<1,"EN CURSO","OK")) -> EN CURSO | E13: =IF($B13="","Sin iniciar",IF($B13<1,"Quedan acciones pendientes antes de cerrar el día.","Checklist completo.")) -> Quedan acciones pendientes antes de cerrar el día. | F13: Revisar la hoja 1 antes de irte: las acciones de cierre son las que sostienen la próxima visita.
A14: Solicitud de datos entregada y recibida | B14: =IF('10 Solicitud datos'!$F$3="","",'10 Solicitud datos'!$F$3) -> 0 | C14: 100% | D14: =IF($B14="","—",IF($B14<1,"EN CURSO","OK")) -> EN CURSO | E14: =IF($B14="","Sin entregar",IF($B14<1,"Sin el dato crudo no hay análisis la próxima semana.","Información completa recibida.")) -> Sin el dato crudo no hay análisis la próxima semana. | F14: Dejar la solicitud firmada con nombre y fecha antes de salir. Sin nombre no hay compromiso.
A16: CÓMO SE USA — Los estados se calculan contra referencias de industria, no contra la meta de Madrid. Sirven para ordenar por dónde empezar. Hay una precedencia que conviene respetar: primero exactitud de inventario, después espacio, después slotting, después método, y de último los controles de verificación. Atacar el orden al revés cuesta el doble y rinde la mitad.

Sheet 1 Checklist
A1: CHECKLIST DEL DÍA
A2: Veinte acciones en el orden en que se hacen. Marca Sí en «Hecho»; el avance se calcula solo y aparece en Resumen.
C3: AVANCE DEL CHECKLIST | D3: =IF(COUNTA($C$8:$C$27)=0,"",COUNTIF($D$8:$D$27,"Sí")/COUNTA($C$8:$C$27)) -> 0
A7: # | B7: Bloque | C7: Acción | D7: Cómo se hace | E7: Hecho | F7: Hora | G7: Responsable | H7: Observación
A8: 1 | B8: Antes de bajarte | C8: Reunión de apertura de máximo 10 minutos, de pie. | D8: Si te sientas dos horas a ver presentaciones, cuando salgas el CEDI ya se organizó.
A9: 2 | B9: Antes de bajarte | C9: Preguntar hora de corte de pedidos y del último camión. | D9: Es el eje del día. Planea estar en despacho las tres horas previas al corte.
A10: 3 | B10: Antes de bajarte | C10: Anunciar: se mide el proceso, no a las personas. | D10: Dilo en el primer minuto y repítelo. Si creen que vienes a sancionar, los datos se dañan hoy.
A11: 4 | B11: Antes de bajarte | C11: Verificar EPP: botas, chaleco, casco si aplica. | D11: Llegar sin EPP cuesta 40 minutos de espera y credibilidad.
A12: 5 | B12: Primeros 30 min | C12: Etiquetar con fecha y hora cada pallet que esté en piso. | D12: Cinta de enmascarar y marcador. Foto del conjunto. Registra en la hoja 7.
A13: 6 | B13: Primeros 30 min | C13: Abrir planilla de vehículos en portería. | D13: Placa, hora de llegada, entrada a muelle y salida. Pide también los últimos 30 días.
A14: 7 | B14: Primeros 30 min | C14: Encargar el conteo ciego de 100 ubicaciones. | D14: Las eliges tú del listado. Quien cuenta no puede ver la cantidad del sistema.
A15: 8 | B15: Primeros 30 min | C15: Seis fotos con hora de puntos fijos. | D15: Muelle, staging, pasillo principal, picking, recepción, devoluciones. Repite en el pico y al cierre.
A16: 9 | B16: Recorrido | C16: Recorrer a contracorriente: del muelle de salida hacia recepción. | D16: Ves el flujo como lo sufre el cliente y cada atasco te lleva a su causa aguas arriba.
A17: 10 | B17: Recorrido | C17: Repetir el recorrido en el pico, antes del corte. | D17: Hora valle y hora pico son dos CEDI distintos. El pico es donde nacen los errores.
A18: 11 | B18: Mediciones | C18: Contar ocupación en 5 pasillos elegidos al azar. | D18: Hoja 2. Trae las reglas para clasificar ocupada, parcial y vacía.
A19: 12 | B19: Mediciones | C19: Cronometrar el ciclo completo de 4 operarios. | D19: Hoja 3. Dos operarios veteranos y dos con menos de 90 días.
... A27: 20 | B27: Al cierre | C27: Acordar una sola acción que empieza mañana y fijar la segunda visita. | D27: Una, no diez. Vuelve en otro día de la semana: el perfil de carga cambia.

Sheet 2 Ocupación
A1: 2 · OCUPACIÓN REAL DE POSICIONES
A2: Cuánto espacio queda de verdad y cuánto está bloqueado sin almacenar nada.
A4: CÓMO SE HACE
A5: OBJETIVO | B5: Saber si el CEDI está en congestión y cuánta capacidad está desperdiciada en posiciones a medio llenar.
A6: QUIÉN LO HACE | B6: Tú solo. No necesitas que te acompañen — y es mejor que no lo hagan.
A7: CUÁNTO DEMORA | B7: 30 minutos.
A8: QUÉ NECESITAS | B8: El listado o el plano de pasillos, y esta hoja.
A9: PASO A PASO
A10: 1 | B10: Pide el listado de pasillos. Elige 5 al azar tú mismo: toma el primero, el que está a un tercio, el de la mitad, el de dos tercios y el último. No dejes que te sugieran cuáles ver.
A11: 2 | B11: Párate al inicio del pasillo y recórrelo contando las posiciones de un solo lado, módulo por módulo, de piso a techo.
A12: 3 | B12: Clasifica cada posición en una de tres: ocupada, parcial o vacía. Usa las reglas de abajo cuando dudes.
A13: 4 | B13: Repite del otro lado del pasillo y suma. Registra el pasillo completo en una sola fila.
A14: 5 | B14: Anota en «Observación» cualquier cosa rara: racks dañados, posiciones bloqueadas, producto sin rotular.
A15: REGLAS PARA NO DUDAR AL LLENAR
A16: ▪ | B16: OCUPADA: el hueco está lleno y no cabe otro pallet. Si un pallet sobredimensionado invade dos posiciones, cuenta 2 ocupadas.
A17: ▪ | B17: PARCIAL: hay producto pero queda espacio útil desperdiciado — media estiba, dos cajas sueltas, un pallet bajo en un hueco alto. Regla práctica: si cabría más y no cabe por cómo está acomodado, es parcial.
A18: ▪ | B18: VACÍA: no hay nada. Una posición reservada en el sistema pero físicamente vacía cuenta como vacía.
A19: ▪ | B19: Posición bloqueada por daño o señalización: cuenta como ocupada y anótalo en Observación.
A20: SI EL RESULTADO SALE MAL, PREGUNTA ESTO
A21: ? | B21: ¿Cuántas posiciones habilitadas tiene el CEDI y cuántas dice el sistema que están ocupadas hoy? Compara con tu conteo: la brecha es error del sistema.
A22: ? | B22: ¿Cuántas de esas posiciones tienen producto sin salidas en los últimos 90 días?
A23: ? | B23: ¿Cuándo fue la última consolidación de posiciones parciales y quién la ordena?
A24: ? | B24: ¿Qué decisión de compra o de promoción explica el inventario que entró en las últimas 13 semanas?
A26: Pasillo / zona | B26: Ocupadas | C26: Parciales | D26: Vacías | E26: Total posiciones | F26: % Ocupación | G26: % Capacidad fantasma | H26: Observación
A27: EJEMPLO ▸ Pasillo 12 | B27: 78 | C27: 14 | D27: 8 | E27: =IF(SUM(B27:D27)=0,"",SUM(B27:D27)) -> 100 | F27: =IF($E27="","",($B27+$C27)/$E27) -> 0.92 | G27: =IF($E27="","",$C27/$E27) -> 0.14 | H27: 3 posiciones con rack doblado
E28: =IF(SUM(B28:D28)=0,"",SUM(B28:D28)) | F28: =IF($E28="","",($B28+$C28)/$E28) | G28: =IF($E28="","",$C28/$E28)
E29: =IF(SUM(B29:D29)=0,"",SUM(B29:D29)) | F29: =IF($E29="","",($B29+$C29)/$E29) | G29: =IF($E29="","",$C29/$E29)
E30: =IF(SUM(B30:D30)=0,"",SUM(B30:D30)) | F30: =IF($E30="","",($B30+$C30)/$E30) | G30: =IF($E30="","",$C30/$E30)
E31: =IF(SUM(B31:D31)=0,"",SUM(B31:D31)) | F31: =IF($E31="","",($B31+$C31)/$E31) | G31: =IF($E31="","",$C31/$E31)
E32: =IF(SUM(B32:D32)=0,"",SUM(B32:D32)) | F32: =IF($E32="","",($B32+$C32)/$E32) | G32: =IF($E32="","",$C32/$E32)
E33: =IF(SUM(B33:D33)=0,"",SUM(B33:D33)) | F33: =IF($E33="","",($B33+$C33)/$E33) | G33: =IF($E33="","",$C33/$E33)
E34: =IF(SUM(B34:D34)=0,"",SUM(B34:D34)) | F34: =IF($E34="","",($B34+$C34)/$E34) | G34: =IF($E34="","",$C34/$E34)
E35: =IF(SUM(B35:D35)=0,"",SUM(B35:D35)) | F35: =IF($E35="","",($B35+$C35)/$E35) | G35: =IF($E35="","",$C35/$E35)
E36: =IF(SUM(B36:D36)=0,"",SUM(B36:D36)) | F36: =IF($E36="","",($B36+$C36)/$E36) | G36: =IF($E36="","",$C36/$E36)
E37: =IF(SUM(B37:D37)=0,"",SUM(B37:D37)) | F37: =IF($E37="","",($B37+$C37)/$E37) | G37: =IF($E37="","",$C37/$E37)
A38: TOTAL DE LA MUESTRA | B38: =SUM(B28:B37) -> 0 | C38: =SUM(C28:C37) -> 0 | D38: =SUM(D28:D37) -> 0 | E38: =SUM(E28:E37) -> 0 | F38: =IF($E$38=0,"",($B$38+$C$38)/$E$38) | G38: =IF($E$38=0,"",$C$38/$E$38)
A40: CÓMO SE LEE — Por encima de 85% cada punto adicional de ocupación cuesta cada vez más; por encima de 90% la operación entra en congestión: doble manipulación, más búsqueda, más errores. Mientras estés ahí, cualquier medición de productividad que tomes está contaminada. La capacidad fantasma es espacio que el sistema ve ocupado y no almacena nada: se recupera consolidando, sin comprar un metro más.

Sheet 3 Ciclo picking
A1: 3 · CICLO DE ALISTAMIENTO
A2: Si el tiempo se va caminando o alistando. Es la diferencia entre un problema de slotting y uno de método.
A4: CÓMO SE HACE
A5: OBJETIVO | B5: Separar el tiempo que agrega valor (tomar producto) del que solo transporta al operario (caminar).
A6: QUIÉN LO HACE | B6: Tú, con cronómetro. Avisa al supervisor antes de empezar.
A7: CUÁNTO DEMORA | B7: 2 horas: unos 30 minutos por operario.
A8: QUÉ NECESITAS | B8: Cronómetro (el del celular sirve) y esta hoja.
A9: PASO A PASO
A10: 1 | B10: Escoge 4 operarios: dos veteranos y dos con menos de 90 días. Pregúntale a cada uno cuánto lleva en el cargo.
A11: 2 | B11: Dile: «voy a acompañarlo, trabaje normal, no estoy calificando a nadie». Camina detrás, nunca al lado ni adelante.
A12: 3 | B12: Arranca el cronómetro cuando reciba la orden de alistamiento y párala cuando entregue el pedido terminado.
A13: 4 | B13: Lleva dos tiempos por separado: CAMINANDO mientras se desplaza sin manipular, y TOMANDO mientras toma, cuenta, empaca, rotula o escanea.
A14: 5 | B14: Cuenta las líneas del pedido y marca una raya cada vez que ocurra una incidencia (no encontró, posición vacía, devolvió, preguntó).
A15: 6 | B15: Observa una cosa más y anótala: si lee el scanner en cada línea o se lo salta.
A16: REGLAS PARA NO DUDAR AL LLENAR
A17: ▪ | B17: El viaje de regreso al punto de partida CUENTA como caminando.
A18: ▪ | B18: Buscar parado frente a la posición cuenta como TOMANDO (es una toma fallida). Si se va a otra posición a buscar, cuenta como CAMINANDO.
A19: ▪ | B19: Si lo interrumpen (montacargas, supervisor, llamada), pausa el cronómetro y anótalo en Observación.
A20: ▪ | B20: «No encontró» es que el producto no estaba donde el sistema decía. «Posición vacía» es que estaba agotada en picking. No son lo mismo.
A21: ▪ | B21: Un solo ciclo por operario basta. Cuatro operarios distintos valen más que cuatro ciclos del mismo.
A22: SI EL RESULTADO SALE MAL, PREGUNTA ESTO
A23: ? | B23: ¿Cuándo fue el último re-slotting y con qué criterio se hizo?
A24: ? | B24: ¿Los 50 SKU de mayor rotación están en la zona dorada, entre cintura y hombro y cerca del muelle?
A25: ? | B25: ¿El recorrido de alistamiento lo define el sistema o lo escoge el operario?
A26: ? | B26: ¿Existe un estándar de líneas por hora y el operario lo conoce?
A28: Operario | B28: Antigüedad | C28: Seg. caminando | D28: Seg. tomando | E28: Ciclo total (s) | F28: % desplazamiento | G28: Líneas | H28: Seg. por línea | I28: No encontró | J28: Posición vacía | K28: Devolvió | L28: Preguntó | M28: ¿Escaneó todo? | N28: Observación
A29: EJEMPLO ▸ J. Ramírez | B29: 4 años | C29: 412 | D29: 298 | E29: =IF(OR($C29="",$D29=""),"",$C29+$D29) -> 710 | F29: =IF($E29="","",$C29/$E29) -> 0.58028169 | G29: 22 | H29: =IF(OR($E29="",$G29=""),"",IFERROR($E29/$G29,"")) -> 32.272727 | I29: 3 | J29: 1 | K29: 0 | L29: 2 | M29: No | N29: Interrumpido 40 s por montacargas
E30: =IF(OR($C30="",$D30=""),"",$C30+$D30) | F30: =IF($E30="","",$C30/$E30) | H30: =IF(OR($E30="",$G30=""),"",IFERROR($E30/$G30,""))
E31: =IF(OR($C31="",$D31=""),"",$C31+$D31) | F31: =IF($E31="","",$C31/$E31) | H31: =IF(OR($E31="",$G31=""),"",IFERROR($E31/$G31,""))
E32: =IF(OR($C32="",$D32=""),"",$C32+$D32) | F32: =IF($E32="","",$C32/$E32) | H32: =IF(OR($E32="",$G32=""),"",IFERROR($E32/$G32,""))
E33: =IF(OR($C33="",$D33=""),"",$C33+$D33) | F33: =IF($E33="","",$C33/$E33) | H33: =IF(OR($E33="",$G33=""),"",IFERROR($E33/$G33,""))
E34: =IF(OR($C34="",$D34=""),"",$C34+$D34) | F34: =IF($E34="","",$C34/$E34) | H34: =IF(OR($E34="",$G34=""),"",IFERROR($E34/$G34,""))
E35: =IF(OR($C35="",$D35=""),"",$C35+$D35) | F35: =IF($E35="","",$C35/$E35) | H35: =IF(OR($E35="",$G35=""),"",IFERROR($E35/$G35,""))
E36: =IF(OR($C36="",$D36=""),"",$C36+$D36) | F36: =IF($E36="","",$C36/$E36) | H36: =IF(OR($E36="",$G36=""),"",IFERROR($E36/$G36,""))
E37: =IF(OR($C37="",$D37=""),"",$C37+$D37) | F37: =IF($E37="","",$C37/$E37) | H37: =IF(OR($E37="",$G37=""),"",IFERROR($E37/$G37,""))
A38: TOTAL / PROMEDIO PONDERADO | C38: =IF(SUM(C30:C37)=0,"",SUM(C30:C37)) | D38: =IF(SUM(D30:D37)=0,"",SUM(D30:D37)) | E38: =IF(SUM(E30:E37)=0,"",SUM(E30:E37)) | F38: =IF(SUM($E$30:$E$37)=0,"",SUM($C$30:$C$37)/SUM($E$30:$E$37)) | G38: =IF(SUM(G30:G37)=0,"",SUM(G30:G37)) | H38: =IF(OR(SUM($E$30:$E$37)=0,SUM($G$30:$G$37)=0),"",SUM($E$30:$E$37)/SUM($G$30:$G$37)) | I38: =IF(SUM(I30:I37)=0,"",SUM(I30:I37)) | J38: =IF(SUM(J30:J37)=0,"",SUM(J30:J37)) | K38: =IF(SUM(K30:K37)=0,"",SUM(K30:K37)) | L38: =IF(SUM(L30:L37)=0,"",SUM(L30:L37))
A40: CÓMO SE LEE — Si caminar pasa del 50% del ciclo, el problema es el slotting y no la gente: correr más rápido no arregla una ruta mal diseñada. Las incidencias de «no encontró» y «posición vacía» apuntan a exactitud de inventario y a reabastecimiento. Si el operario se salta el escaneo, ningún control posterior va a sostener la calidad del despacho.

Sheet 4 Conteo ciego
A1: 4 · CONTEO CIEGO — EXACTITUD DE INVENTARIO (ERI)
A2: Si el sistema dice la verdad sobre dónde está el producto y cuánto hay. Decide el orden de todo el plan.
A4: CÓMO SE HACE
A5: OBJETIVO | B5: Medir qué porcentaje de las ubicaciones tiene exactamente lo que el sistema dice que tiene.
A6: QUIÉN LO HACE | B6: Un auxiliar que NO sea el responsable de esa zona, acompañado por ti al inicio.
A7: CUÁNTO DEMORA | B7: 2 a 3 horas de conteo. El resultado se cierra al final del día.
A8: QUÉ NECESITAS | B8: Listado de ubicaciones ocupadas SIN la columna de cantidad, y una planilla en blanco.
A9: PASO A PASO
A10: 1 | B10: Pide el listado de ubicaciones ocupadas. Elige tú 100 al azar — por ejemplo, una de cada N. No aceptes «le preparo una zona».
A11: 2 | B11: Imprime la lista SIN la columna de cantidad. Eso es lo que hace ciego el conteo: quien cuenta no sabe qué debería encontrar.
A12: 3 | B12: El auxiliar recorre y anota lo que ve, ubicación por ubicación, sin consultar el sistema ni preguntarle a nadie.
A13: 4 | B13: Pasa lo contado a la columna «Cant. contada» de esta hoja.
A14: 5 | B14: AL FINAL DEL DÍA pide al sistema la cantidad de esas 100 ubicaciones y llénala en «Cant. sistema». El ERI se calcula solo.
A15: REGLAS PARA NO DUDAR AL LLENAR
A16: ▪ | B16: Es binario: la ubicación está exacta o no lo está. Una sola unidad de diferencia ya es NO.
A17: ▪ | B17: Si en la ubicación hay un SKU distinto al que dice el sistema, es NO aunque la cantidad coincida.
A18: ▪ | B18: Si la ubicación está vacía y el sistema dice que hay producto, escribe 0 en «Cant. contada». Cuenta como NO.
A19: ▪ | B19: No promedies en pesos ni en valor: faltantes y sobrantes se compensan y siempre se ve bien.
A20: ▪ | B20: Si el auxiliar ve la cantidad del sistema antes de contar, el conteo se invalida. Repítelo con otras ubicaciones.
A21: SI EL RESULTADO SALE MAL, PREGUNTA ESTO
A22: ? | B22: ¿Cada cuánto hacen conteos cíclicos, quién los hace y qué se hace con el resultado?
A23: ? | B23: ¿Qué pasa cuando un operario encuentra una diferencia? ¿La puede reportar sin que lo sancionen?
A24: ? | B24: ¿Quién tiene permiso para ajustar inventario en el sistema y con qué autorización?
A25: ? | B25: ¿Cuántos ajustes de inventario se hicieron el mes pasado y por qué causal?
A27: Ubicaciones contadas | B27: =COUNTIF($F$31:$F$130,"SÍ")+COUNTIF($F$31:$F$130,"NO") -> 0 | C27: Exactas | D27: =COUNTIF($F$31:$F$130,"SÍ") -> 0 | E27: ERI por ubicación | F27: =IF($B$27=0,"",$D$27/$B$27)
A29: # | B29: Ubicación | C29: SKU | D29: Cant. contada | E29: Cant. sistema | F29: ¿Exacta? | G29: Diferencia | H29: Observación
A30: EJ | B30: A-12-03-B | C30: SKU 100482 | D30: 48 | E30: 52 | F30: =IF(OR($D30="",$E30=""),"",IF($D30=$E30,"SÍ","NO")) -> NO | G30: =IF(OR($D30="",$E30=""),"",$D30-$E30) -> -4 | H30: Producto de otra referencia mezclado
A31: 1 | F31: =IF(OR($D31="",$E31=""),"",IF($D31=$E31,"SÍ","NO")) | G31: =IF(OR($D31="",$E31=""),"",$D31-$E31)
A32: 2 | F32: =IF(OR($D32="",$E32=""),"",IF($D32=$E32,"SÍ","NO")) | G32: =IF(OR($D32="",$E32=""),"",$D32-$E32)
A33: 3 | F33: =IF(OR($D33="",$E33=""),"",IF($D33=$E33,"SÍ","NO")) | G33: =IF(OR($D33="",$E33=""),"",$D33-$E33)
A34: 4 | F34: =IF(OR($D34="",$E34=""),"",IF($D34=$E34,"SÍ","NO")) | G34: =IF(OR($D34="",$E34=""),"",$D34-$E34)
A35: 5 | F35: =IF(OR($D35="",$E35=""),"",IF($D35=$E35,"SÍ","NO")) | G35: =IF(OR($D35="",$E35=""),"",$D35-$E35)
A36: 6 | F36: =IF(OR($D36="",$E36=""),"",IF($D36=$E36,"SÍ","NO")) | G36: =IF(OR($D36="",$E36=""),"",$D36-$E36)
A37: 7 | F37: =IF(OR($D37="",$E37=""),"",IF($D37=$E37,"SÍ","NO")) | G37: =IF(OR($D37="",$E37=""),"",$D37-$E37)
A38: 8 | F38: =IF(OR($D38="",$E38=""),"",IF($D38=$E38,"SÍ","NO")) | G38: =IF(OR($D38="",$E38=""),"",$D38-$E38)
A39: 9 | F39: =IF(OR($D39="",$E39=""),"",IF($D39=$E39,"SÍ","NO")) | G39: =IF(OR($D39="",$E39=""),"",$D39-$E39)
A40: 10 | F40: =IF(OR($D40="",$E40=""),"",IF($D40=$E40,"SÍ","NO")) | G40: =IF(OR($D40="",$E40=""),"",$D40-$E40)
A41: 11 | F41: =IF(OR($D41="",$E41=""),"",IF($D41=$E41,"SÍ","NO")) | G41: =IF(OR($D41="",$E41=""),"",$D41-$E41)
A42: 12 | F42: =IF(OR($D42="",$E42=""),"",IF($D42=$E42,"SÍ","NO")) | G42: =IF(OR($D42="",$E42=""),"",$D42-$E42)
... A130: 100 | F130: =IF(OR($D130="",$E130=""),"",IF($D130=$E130,"SÍ","NO")) | G130: =IF(OR($D130="",$E130=""),"",$D130-$E130)

Sheet 5 Muestreo
A1: 5 · MUESTREO DE TRABAJO
A2: Qué proporción del día agrega valor. Convierte «la gente no rinde» en «el diseño no deja rendir».
A4: CÓMO SE HACE
A5: OBJETIVO | B5: Estimar cómo se reparte el tiempo real de la operación entre alistar, caminar, buscar, esperar y reprocesar.
A6: QUIÉN LO HACE | B6: Tú, o alguien ajeno al área. Avisa al supervisor para que no se lea como vigilancia.
A7: CUÁNTO DEMORA | B7: Todo el día, pero solo 2 minutos cada 20.
A8: QUÉ NECESITAS | B8: Un punto alto o despejado desde donde veas varias personas a la vez.
A9: PASO A PASO
A10: 1 | B10: Escoge un punto donde alcances a ver varias personas al mismo tiempo: un altillo, el final de un pasillo, la plataforma de un muelle.
A11: 2 | B11: Cada 20 minutos mira UNA sola vez y anota qué está haciendo cada persona EN ESE INSTANTE EXACTO. No lo que venía haciendo ni lo que va a hacer.
A12: 3 | B12: Una fila por persona y por ronda. Con 12 rondas y 15 personas llegas a 180 observaciones, que es una muestra válida.
A13: 4 | B13: Anota el puesto o la zona, nunca el nombre. Esto mide el proceso, no a las personas.
A14: 5 | B14: El resumen de la derecha se llena solo a medida que registras.
A15: REGLAS PARA NO DUDAR AL LLENAR
A16: ▪ | B16: ALISTANDO: tomar, contar, empacar, rotular, escanear. Es lo único que agrega valor al pedido.
A17: ▪ | B17: REABASTECIENDO: mover producto hacia posición de picking. Necesario, pero no agrega valor al pedido.
A18: ▪ | B18: CAMINANDO: desplazarse, con o sin producto, sin manipular.
A19: ▪ | B19: BUSCANDO: parado mirando, revisando pantalla o preguntando dónde está algo.
A20: ▪ | B20: ESPERANDO: quieto por falta de producto, de equipo, de documento o de instrucción.
A21: ▪ | B21: REPROCESANDO: corregir, devolver o rehacer un pedido ya alistado.
A22: ▪ | B22: OTRO: conversar, baño, descanso o actividad ajena a la operación. No lo escondas: distorsiona la muestra.
A23: SI EL RESULTADO SALE MAL, PREGUNTA ESTO
A24: ? | B24: ¿Existe un estándar de líneas por hora y el operario lo conoce?
A25: ? | B25: ¿Cada cuánto se reabastece la zona de picking y quién decide cuándo?
A26: ? | B26: ¿Qué hace un operario cuando se queda sin trabajo asignado?
A27: ? | B27: ¿Cuántas veces al día se detiene la operación por falta de equipo o de montacargas?
A29: Ronda | B29: Hora | C29: Puesto / zona | D29: Actividad | F29: Actividad | G29: Observaciones | H29: % | I29: Nota
A30: 1 | B30: 09:20 | C30: Picking pasillo 8 | D30: Caminando | F30: Alistando | G30: =COUNTIF($D$31:$D$230,$F30) -> 0 | H30: =IF($G$37=0,"",$G30/$G$37)
F31: Reabasteciendo | G31: =COUNTIF($D$31:$D$230,$F31) -> 0 | H31: =IF($G$37=0,"",$G31/$G$37)
F32: Caminando | G32: =COUNTIF($D$31:$D$230,$F32) -> 0 | H32: =IF($G$37=0,"",$G32/$G$37)
F33: Buscando | G33: =COUNTIF($D$31:$D$230,$F33) -> 0 | H33: =IF($G$37=0,"",$G33/$G$37)
F34: Esperando | G34: =COUNTIF($D$31:$D$230,$F34) -> 0 | H34: =IF($G$37=0,"",$G34/$G$37)
F35: Reprocesando | G35: =COUNTIF($D$31:$D$230,$F35) -> 0 | H35: =IF($G$37=0,"",$G35/$G$37)
F36: Otro | G36: =COUNTIF($D$31:$D$230,$F36) -> 0 | H36: =IF($G$37=0,"",$G36/$G$37)
F37: TOTAL OBSERVACIONES | G37: =SUM($G$30:$G$36) -> 0
F39: NO AGREGA VALOR | G39: =SUM($G$32:$G$36) -> 0 | H39: =IF($G$37=0,"",$G$39/$G$37)
F41: CÓMO SE LEE — En CEDI sin estándares de trabajo es normal encontrar 30–45% del tiempo en desplazamiento y 10–20% buscando. Si «no agrega valor» pasa del 50%, más de la mitad del día se está yendo en el diseño de la operación, no en el esfuerzo de la gente.

Sheet 6 Vehículos
A1: 6 · PERMANENCIA DE VEHÍCULOS EN MUELLE
A2: Si el cuello de botella está en el muelle, en la programación de citas o en el alistamiento.
A4: CÓMO SE HACE
A5: OBJETIVO | B5: Medir cuánto tiempo pierde un vehículo entre que llega y que sale, y en qué parte se pierde.
A6: QUIÉN LO HACE | B6: Portería registra durante el día; tú recoges la planilla al cierre.
A7: CUÁNTO DEMORA | B7: 2 minutos por vehículo para portería. 15 minutos para ti al final.
A8: QUÉ NECESITAS | B8: Una planilla en portería y el reloj de la garita.
A9: PASO A PASO
A10: 1 | B10: Pide en portería que registren cada vehículo del día con tres horas: llegada a portería, entrada al muelle y salida.
A11: 2 | B11: Si ya llevan ese registro, pide además los últimos 30 días: te da la tendencia sin esperar.
A12: 3 | B12: Al cierre del día recoge la planilla y pásala a esta hoja.
A13: 4 | B13: Pregunta por los vehículos que llegaron antes que tú y complétalos con el dato de portería.
A14: 5 | B14: Los minutos de espera, cargue y permanencia se calculan solos.
A15: REGLAS PARA NO DUDAR AL LLENAR
A16: ▪ | B16: Escribe las horas en formato HH:MM. Por ejemplo 08:15, no «8 y cuarto» ni «8:15 am».
A17: ▪ | B17: ESPERA es desde que llega a portería hasta que entra al muelle. Es tiempo perdido puro.
A18: ▪ | B18: CARGUE es desde que entra al muelle hasta que sale. Incluye documentos y precintado.
A19: ▪ | B19: Si un vehículo entró y salió sin cargar, regístralo igual y anótalo en Observación.
A20: ▪ | B20: Si no tienes la hora exacta de entrada al muelle, deja la celda vacía: es mejor un dato faltante que uno inventado.
A21: SI EL RESULTADO SALE MAL, PREGUNTA ESTO
A22: ? | B22: ¿Existe sistema de citas para los vehículos y quién lo administra?
A23: ? | B23: ¿Cuántos muelles hay habilitados y cuántos se usan al mismo tiempo?
A24: ? | B24: ¿El pedido ya está alistado cuando llega el vehículo, o se alista con el vehículo esperando?
A25: ? | B25: ¿Cuánto le cobra el transportador a la compañía por hora de espera?
A27: Placa | B27: Transportista | C27: Hora llegada | D27: Hora entrada muelle | E27: Hora salida | F27: Espera (min) | G27: Cargue (min) | H27: Permanencia total (min) | I27: Observación
A28: EJ ▸ ABC123 | B28: Transportes Norte | C28: 07:40 | D28: 09:05 | E28: 10:20 | F28: =IF(OR($C28="",$D28=""),"",($D28-$C28)*1440) -> 85 | G28: =IF(OR($D28="",$E28=""),"",($E28-$D28)*1440) -> 75 | H28: =IF(OR($C28="",$E28=""),"",($E28-$C28)*1440) -> 160 | I28: Esperó porque el pedido no estaba alistado
F29: =IF(OR($C29="",$D29=""),"",($D29-$C29)*1440) | G29: =IF(OR($D29="",$E29=""),"",($E29-$D29)*1440) | H29: =IF(OR($C29="",$E29=""),"",($E29-$C29)*1440)
F30: =IF(OR($C30="",$D30=""),"",($D30-$C30)*1440) | G30: =IF(OR($D30="",$E30=""),"",($E30-$D30)*1440) | H30: =IF(OR($C30="",$E30=""),"",($E30-$C30)*1440)
F31: =IF(OR($C31="",$D31=""),"",($D31-$C31)*1440) | G31: =IF(OR($D31="",$E31=""),"",($E31-$D31)*1440) | H31: =IF(OR($C31="",$E31=""),"",($E31-$C31)*1440)
F32: =IF(OR($C32="",$D32=""),"",($D32-$C32)*1440) | G32: =IF(OR($D32="",$E32=""),"",($E32-$D32)*1440) | H32: =IF(OR($C32="",$E32=""),"",($E32-$C32)*1440)
F33: =IF(OR($C33="",$D33=""),"",($D33-$C33)*1440) | G33: =IF(OR($D33="",$E33=""),"",($E33-$D33)*1440) | H33: =IF(OR($C33="",$E33=""),"",($E33-$C33)*1440)
F34: =IF(OR($C34="",$D34=""),"",($D34-$C34)*1440) | G34: =IF(OR($D34="",$E34=""),"",($E34-$D34)*1440) | H34: =IF(OR($C34="",$E34=""),"",($E34-$C34)*1440)
F35: =IF(OR($C35="",$D35=""),"",($D35-$C35)*1440) | G35: =IF(OR($D35="",$E35=""),"",($E35-$D35)*1440) | H35: =IF(OR($C35="",$E35=""),"",($E35-$C35)*1440)
F36: =IF(OR($C36="",$D36=""),"",($D36-$C36)*1440) | G36: =IF(OR($D36="",$E36=""),"",($E36-$D36)*1440) | H36: =IF(OR($C36="",$E36=""),"",($E36-$C36)*1440)
F37: =IF(OR($C37="",$D37=""),"",($D37-$C37)*1440) | G37: =IF(OR($D37="",$E37=""),"",($E37-$D37)*1440) | H37: =IF(OR($C37="",$E37=""),"",($E37-$C37)*1440)
F38: =IF(OR($C38="",$D38=""),"",($D38-$C38)*1440) | G38: =IF(OR($D38="",$E38=""),"",($E38-$D38)*1440) | H38: =IF(OR($C38="",$E38=""),"",($E38-$C38)*1440)
F39: =IF(OR($C39="",$D39=""),"",($D39-$C39)*1440) | G39: =IF(OR($D39="",$E39=""),"",($E39-$D39)*1440) | H39: =IF(OR($C39="",$E39=""),"",($E39-$C39)*1440)
F40: =IF(OR($C40="",$D40=""),"",($D40-$C40)*1440) | G40: =IF(OR($D40="",$E40=""),"",($E40-$D40)*1440) | H40: =IF(OR($C40="",$E40=""),"",($E40-$C40)*1440)
... F48: =IF(OR($C48="",$D48=""),"",($D48-$C48)*1440) | G48: =IF(OR($D48="",$E48=""),"",($E48-$D48)*1440) | H48: =IF(OR($C48="",$E48=""),"",($E48-$C48)*1440)
A49: PROMEDIO | F49: =IF(COUNT(F29:F48)=0,"",AVERAGE(F29:F48)) | G49: =IF(COUNT(G29:G48)=0,"",AVERAGE(G29:G48)) | H49: =IF(COUNT(H29:H48)=0,"",AVERAGE(H29:H48))
...

Sheet 7 Pallets en piso
A1: 7 · PALLETS EN PISO — PRUEBA DE LA ETIQUETA DE FECHA
A2: El dato más contundente del día, y cuesta una caja de etiquetas.
A4: CÓMO SE HACE
A5: OBJETIVO | B5: Cuantificar el producto que está fuera de posición y, a las 48 horas, saber cuánto de eso es backlog real y no tránsito.
A6: QUIÉN LO HACE | B6: Tú, con cinta de enmascarar y marcador grueso.
A7: CUÁNTO DEMORA | B7: 40 minutos hoy. 15 minutos a las 48 horas.
A8: QUÉ NECESITAS | B8: Cinta de enmascarar, marcador y la cámara del celular.
A9: PASO A PASO
A10: 1 | B10: Recorre todas las zonas donde pueda haber producto fuera de posición: recepción, staging, pasillos de maniobra, devoluciones, averías, cuarentena.
A11: 2 | B11: Pega una etiqueta con FECHA Y HORA en cada pallet que esté fuera de posición. No te saltes ninguno.
A12: 3 | B12: Cuenta los pallets por zona y regístralos aquí, una fila por zona.
A13: 4 | B13: Toma una foto del conjunto de cada zona, con la hora visible.
A14: 5 | B14: VUELVE A LAS 48 HORAS (o pide una foto de las mismas zonas) y marca en la columna correspondiente cuáles siguen ahí con la etiqueta original.
A15: REGLAS PARA NO DUDAR AL LLENAR
A16: ▪ | B16: «Fuera de posición» es todo producto que no está en una ubicación del sistema.
A17: ▪ | B17: Incluye lo que esté en pasillos de maniobra aunque te digan «es que ya se va». Precisamente eso es lo que estás midiendo.
A18: ▪ | B18: Si hay producto apilado sin pallet, cuéntalo como pallets equivalentes y anótalo en Observación.
A19: ▪ | B19: No cuentes el producto que está en un muelle con vehículo cargando: eso sí es tránsito real.
A20: SI EL RESULTADO SALE MAL, PREGUNTA ESTO
A21: ? | B21: ¿Cuál es el dock-to-stock objetivo y cuál fue el real de la semana pasada?
A22: ? | B22: ¿Quién autoriza la disposición final de devoluciones y averías, y cuándo lo hizo por última vez?
A23: ? | B23: ¿Existe una regla de piso libre al cierre del turno? ¿Quién la verifica?
A24: ? | B24: ¿Qué recepción del último mes se demoró más en quedar disponible y por qué?
A26: Zona | B26: N.º de pallets etiquetados | C26: Producto / descripción | D26: Fecha de la etiqueta | E26: ¿Sigue ahí a las 48 h? | F26: Observación
A27: EJ ▸ Recepción | B27: 18 | C27: Importado sin ubicar, 3 referencias | D27: 24/08/2026 | E27: Sí | F27: Llegó el contenedor el viernes
A28: Recepción
A29: Staging de despacho
A30: Pasillos de maniobra
A31: Devoluciones
A32: Averías
A33: Cuarentena / pendiente de calidad
A34: Cross-dock
A35: Otro
A38: TOTAL PALLETS FUERA DE POSICIÓN | B38: =IF(COUNT(B28:B37)=0,"",SUM(B28:B37))
A40: CÓMO SE LEE — Lo que siga ahí a las 48 horas con la etiqueta original es backlog real, contable y fotografiable: ya no es «producto en tránsito». Es la evidencia que convierte una discusión de percepciones en una cifra que nadie puede discutir en la reunión de gerencia.

Sheet 8 Agotados
A1: 8 · AGOTADOS INTERNOS DE PICKING
A2: La causa oculta número uno de baja productividad, y casi ningún CEDI la mide.
A4: CÓMO SE HACE
A5: OBJETIVO | B5: Contar cuántas veces un operario llega a una posición de picking y no hay producto, teniendo pedido pendiente.
A6: QUIÉN LO HACE | B6: Un supervisor de picking durante todo el turno. Tú solo entregas la planilla y la recoges.
A7: CUÁNTO DEMORA | B7: Todo el turno, pero son 30 segundos por evento.
A8: QUÉ NECESITAS | B8: Esta hoja impresa o una planilla en papel para el supervisor.
A9: PASO A PASO
A10: 1 | B10: Al inicio del turno entrégale la planilla al supervisor de picking.
A11: 2 | B11: Explícale exactamente qué cuenta: cada vez que un operario llegue a una posición y no haya producto con pedido pendiente.
A12: 3 | B12: Pídele que anote hora, SKU, ubicación y cuántos minutos pasaron hasta que llegó el reabastecimiento.
A13: 4 | B13: Aclárale que esto no busca culpables: mide si el reabastecimiento va adelante o detrás del picking.
A14: 5 | B14: Recoge la planilla al cierre del turno y pásala a esta hoja.
A15: REGLAS PARA NO DUDAR AL LLENAR
A16: ▪ | B16: Cuenta el evento aunque el reabastecimiento llegue a los dos minutos. Lo que mides es la frecuencia, no la gravedad.
A17: ▪ | B17: Si el operario se salta la línea y sigue con otra, sigue contando como agotado.
A18: ▪ | B18: Si el producto está en la ubicación pero mal rotulado y el operario no lo reconoce, cuenta como agotado y anótalo.
A19: ▪ | B19: Si no sabes los minutos exactos, deja la celda vacía. El conteo de eventos es lo que importa.
A20: SI EL RESULTADO SALE MAL, PREGUNTA ESTO
A21: ? | B21: ¿Cada cuánto se reabastece la zona de picking y quién decide cuándo?
A22: ? | B22: ¿El reabastecimiento se hace en ola antes del turno o durante el turno según se va agotando?
A23: ? | B23: ¿Existe un punto de reorden por posición de picking o se hace a criterio?
A24: ? | B24: ¿Cuántas personas hay dedicadas a reabastecer frente a cuántas alistando?
A26: Hora | B26: SKU | C26: Ubicación | D26: Minutos sin reabastecer | E26: Pedido afectado | F26: Turno | G26: Observación
A27: 10:35 | B27: SKU 100482 | C27: A-04-01-A | D27: 22 | E27: PED-88213 | F27: Mañana | G27: El operario siguió con otra línea
A68: EVENTOS | B68: =IF(COUNTA(B28:B67)=0,"",COUNTA(B28:B67)) | C68: MINUTOS PERDIDOS | D68: =IF(SUM(D28:D67)=0,"",SUM(D28:D67))
A70: CÓMO SE LEE — Un agotado interno detiene al operario, lo obliga a reordenar su recorrido y muchas veces termina en un faltante al cliente. Si se repiten los mismos SKU, el punto de reorden está mal puesto. Si se concentran en una franja horaria, el reabastecimiento va detrás del picking y debe pasar a ola antes del turno.

Sheet 9 Preguntas
A1: 9 · PREGUNTAS PARA HACER EN PISO
A2: Formuladas tal como se dicen. Cada una trae qué buscar en la respuesta y qué hacer si aparece la señal de alarma.
A4: REGLA GENERAL
A5: ▪ | B5: A los operarios se les pregunta sin el supervisor delante. Si el supervisor está presente, la respuesta es la que él querría oír.
A6: ▪ | B6: Pregunta y cállate. El silencio incómodo después de la respuesta es donde aparece la información que no te iban a dar.
A7: ▪ | B7: Nunca preguntes «¿quién se equivocó?». Cierra la información para el resto del día y para la próxima visita.
A8: PREGUNTAS QUE NO FUNCIONAN Y CON QUÉ REEMPLAZARLAS
A9: En vez de preguntar esto… | B9: …pregunta esto
A10: «¿Por qué está tan lleno?» | B10: «Muéstreme el pallet más viejo que hay en piso.»
A11: «¿Cómo van los indicadores?» | B11: «Muéstreme el dato crudo de la semana pasada, no el reporte.»
A12: «¿Están cumpliendo la meta?» | B12: «¿Cuál fue el peor día del mes y qué pasó ese día?»
A13: «¿Tienen algún problema?» | B13: «Si le dieran una persona más mañana, ¿dónde la pondría y por qué?»
A14: «¿Quién se equivocó?» | B14: «¿Qué tendría que cambiar para que ese error fuera imposible?»
A16: BANCO DE PREGUNTAS
A17: A quién | B17: Pregunta (dila así) | C17: Por qué esta pregunta | D17: Respuesta | E17: Señal de alarma en la respuesta | F17: Qué hacer si aparece la señal
A18: Operario | B18: ¿Qué es lo que más tiempo le hace perder en el día? | C18: Nombra el desperdicio real antes que cualquier indicador. | E18: Menciona caminar o buscar producto. | F18: Contrástalo con la hoja 3: si el desplazamiento pasa de 50%, ya tienes causa y evidencia.
A19: Operario | B19: ¿Cuántas veces al día no encuentra el producto donde dice el sistema? | C19: Estima el ERI sin esperar el conteo ciego. | E19: Más de dos o tres veces al día. | F19: Sube la muestra del conteo ciego y revisa quién puede ajustar inventario.
A20: Operario | B20: Cuando se equivoca, ¿por qué cree que pasó? | C20: Distingue ambigüedad de diseño de falta de método. | E20: Menciona productos parecidos o posiciones vecinas. | F20: Separa físicamente los SKU gemelos: es el control más efectivo y el más barato.
A21: Operario | B21: ¿Cuántas líneas se supone que debe hacer por hora? | C21: Verifica si existe estándar de trabajo. | E21: No sabe, o cada quien dice un número distinto. | F21: No hay estándar. Sin estándar no hay productividad que gestionar, solo esfuerzo individual.
A22: Operario | B22: ¿Qué hay ahí que no debería estar? | C22: Señala inventario muerto y zonas sin dueño. | E22: Señala producto que lleva meses en el mismo sitio. | F22: Anótalo como hallazgo y crúzalo con el inventario sin movimiento mayor a 90 días.
A23: Operario | B23: Si usted mandara aquí, ¿qué cambiaría primero? | C23: La mejor pregunta de cierre. Sabe la respuesta y casi nunca se la piden. | E23: Responde de inmediato y con detalle. | F23: Escríbelo textual en la hoja 11. Suele ser la acción de mayor impacto y menor costo.
A24: Jefe del CEDI | B24: ¿Cuál es su cuello de botella hoy? | C24: Mide si hay gestión o solo reacción. | E24: Responde «todo» o cambia de tema. | F24: No hay gestión por indicadores. Empieza por instalar el tablero diario de cinco cifras.
A25: Jefe del CEDI | B25: ¿Cuántas posiciones tiene y cuántas están ocupadas en este momento? | C25: Contrasta contra tu conteo de la hoja 2. | E25: La cifra difiere mucho de lo que contaste. | F25: El sistema no refleja la realidad física. Prioriza exactitud de inventario.
A26: Jefe del CEDI | B26: ¿Qué pasa cuando un pedido no alcanza a salir? | C26: Revela si hay regla o improvisación. | E26: Depende de quién esté de turno. | F26: Falta regla de priorización. Escríbela y publícala: es una acción de cero costo.
A27: Jefe del CEDI | B27: ¿Cuándo fue el último re-slotting y con qué criterio? | C27: Más de seis meses explica buena parte del desplazamiento. | E27: No recuerda, o se hizo «cuando se organizó la bodega». | F27: Programa un re-slotting de los 200 SKU de mayor rotación. Es el quick win de mayor impacto.
A28: Jefe del CEDI | B28: Si le dieran una persona más mañana, ¿dónde la pondría? | C28: Revela el cuello de botella real sin ponerlo a la defensiva. | E28: Cualquier respuesta sirve: señala dónde duele. | F28: Compáralo con lo que digan los operarios. Si no coinciden, el jefe no está en el piso.
A29: Recepción | B29: ¿Se recibe en flujo o por lotes al final del turno? | C29: El lote al cierre deja producto en piso toda la noche. | E29: Se recibe por lotes o «cuando hay gente». | F29: Es causa directa de dock-to-stock alto y de CEDI lleno. Nivela la recepción durante el turno.
... A34: Gestión humana | B34: ¿Cuánta gente entró y salió del CEDI en los últimos seis meses? | C34: La rotación alta explica errores sin que nadie tenga la culpa. | E34: Rotación por encima del 30% anual. | F34: Con rotación alta siempre vas a tener novatos. Refuerza certificación antes de operar solo.

Sheet 10 Solicitud datos
A1: 10 · SOLICITUD DE INFORMACIÓN
A2: Entrégala hoy, por escrito, con responsable y fecha. Si te vas sin dejarla, pierdes una semana esperando.
E3: AVANCE DE ENTREGA | F3: =IF(COUNTA($C$8:$C$23)=0,"",COUNTIF($G$8:$G$23,"Sí")/COUNTA($C$8:$C$23)) -> 0
A5: CONDICIONES DE LA ENTREGA — DÍSELO ASÍ AL RESPONSABLE
A6: ▪ | B6: Período: últimas 13 semanas. Formato Excel o CSV plano, un registro por fila. Sin tablas dinámicas, sin consolidados, sin resúmenes. Si mandan un reporte ya cocinado no sirve: los promedios esconden el pico de las últimas tres horas antes del corte, el operario con menos de 90 días y los diez SKU que generan la mitad de los errores.
A7: # | B7: Área | C7: Información solicitada | D7: Formato | E7: Responsable | F7: Fecha compromiso | G7: Recibido | H7: Observación
A8: 1 | B8: WMS / ERP | C8: Movimientos de salida a nivel de línea: fecha, hora, SKU, cantidad, ubicación, operario, pedido, cliente y ruta | D8: CSV plano
A9: 2 | B9: WMS / ERP | C9: Movimientos de entrada con hora de llegada del vehículo Y hora de ubicación del producto (dock-to-stock) | D9: CSV plano
A10: 3 | B10: WMS / ERP | C10: Snapshot de inventario por ubicación, al cierre de hoy | D10: CSV plano
A11: 4 | B11: WMS / ERP | C11: Maestro de ubicaciones: posiciones por zona y por tipo | D11: Excel
A12: 5 | B12: WMS / ERP | C12: Maestro de SKU: dimensiones, peso, empaque y paletización | D12: Excel
A13: 6 | B13: WMS / ERP | C13: Trazabilidad de pedidos: creación, corte, liberación, fin de alistamiento y despacho | D13: CSV plano
A14: 7 | B14: WMS / ERP | C14: Devoluciones y notas crédito con su causal | D14: CSV plano
A15: 8 | B15: WMS / ERP | C15: Resultados de los últimos conteos cíclicos y ajustes de inventario con su causal | D15: Excel
A16: 9 | B16: Gestión humana | C16: Headcount por turno y por función | D16: Excel
A17: 10 | B17: Gestión humana | C17: Horas ordinarias y horas extra por período | D17: Excel
A18: 11 | B18: Gestión humana | C18: Ausentismo, rotación y antigüedad promedio | D18: Excel
A19: 12 | B19: Transporte | C19: Vehículos programados frente a ejecutados | D19: Excel
... A23: 16 | B23: Finanzas | C23: Costo total del CEDI del último trimestre | D23: Excel

Sheet 11 Hallazgos
A1: 11 · HALLAZGOS Y COMPROMISOS DEL DÍA
A2: El producto de la visita. Un hallazgo es un hecho con número: si no tiene cifra, es una opinión y no entra aquí.
A4: CÓMO SE ESCRIBE UN HALLAZGO
A5: BIEN | B5: «Conté 5 pasillos: 93% de ocupación y 15% de posiciones parciales.» · «El operario que acompañé caminó el 58% de su ciclo.» · «Hay 40 pallets en piso; les puse etiqueta con fecha de hoy.»
A6: MAL | B6: «La bodega está desordenada.» · «Falta compromiso del personal.» · «Se ve mucho inventario.» Nada de eso se puede medir después ni discutir con datos.
A8: # | B8: Hallazgo (hecho con número) | C8: Evidencia | D8: Causa probable | E8: Acción propuesta | F8: Dueño | G8: Fecha | H8: Prioridad
A9: EJ | B9: Ocupación de 93% en la muestra de 5 pasillos, con 15% de posiciones parciales. | C9: Hoja 2 + fotos 09:15 | D9: Inventario sin movimiento ocupando posiciones y parciales sin consolidar. | E9: Purga de SKU sin salidas mayores a 180 días y consolidación de parciales. | F9: Jefe del CEDI | G9: 15/09/2026 | H9: Alta
A10: 1
A11: 2
A12: 3
A13: 4
A14: 5
A15: 6
A16: 7
A17: 8
A18: 9
A19: 10
A20: 11
A21: 12
... A24: 15
A26: EN LA REUNIÓN DE CIERRE — Devuelve tres hallazgos, no quince. Deja la solicitud de datos firmada. Acuerda UNA sola acción que empiece mañana (normalmente: llevar el registro de agotados de picking, que cuesta cero). Y fija la segunda visita en otro día de la semana: un lunes y un viernes son operaciones distintas.

Sheet Glosario
A1: GLOSARIO
A2: Para que cualquiera del equipo pueda usar este archivo sin tener que preguntar qué significa cada término.
A4: Término | B4: Qué significa | C4: Por qué importa en esta evaluación
A5: CEDI | B5: Centro de distribución: la bodega donde se recibe, almacena, alista y despacha. | C5: Es la unidad que estás evaluando.
A6: SKU | B6: Cada referencia distinta de producto. Dos sabores del mismo artículo son dos SKU. | C6: Los SKU parecidos entre sí son la causa más común de error de despacho.
A7: Línea de pedido | B7: Cada renglón de un pedido: un SKU con su cantidad. | C7: La productividad se mide en líneas por hora, no en unidades.
A8: Posición | B8: Cada hueco de almacenamiento donde cabe un pallet o una cantidad definida. | C8: La ocupación se mide sobre posiciones, no sobre metros cuadrados.
A9: Ocupación | B9: Porcentaje de posiciones ocupadas sobre las habilitadas. | C9: Por encima de 90% la operación entra en congestión.
A10: Capacidad fantasma | B10: Posiciones que el sistema ve ocupadas pero que están a medio llenar. | C10: Es espacio que se recupera consolidando, sin comprar un metro más.
A11: Efecto panal | B11: Huecos inutilizables que quedan entre producto mal acomodado. | C11: Es la forma física de la capacidad fantasma.
A12: Alistamiento (picking) | B12: Tomar de las posiciones los productos que pide un pedido. | C12: Es donde se concentra la mano de obra y donde nacen los errores.
A13: Slotting | B13: La decisión de qué producto va en cuál posición. | C13: Un slotting desactualizado hace caminar de más al operario todo el día.
A14: Zona dorada | B14: Las posiciones entre cintura y hombro, cerca del muelle. | C14: Ahí deben estar los SKU de mayor rotación. Si no lo están, se pierde tiempo en cada línea.
A15: Reabastecimiento | B15: Mover producto desde almacenamiento hasta la posición de picking. | C15: Si va detrás del picking, el operario se queda sin producto.
... A30: Gemba | B30: El lugar donde ocurre el trabajo real. | C30: La evaluación se hace en el piso, no en la sala de juntas.
